Workbook
Name BANJARWANGI: OLT!$J$275:$J$285
Name BANYURESMI: OLT!$J$68:$J$82
Name BAYONGBONG: OLT!$J$198:$J$215
Name BL._LIMBANGAN: OLT!$J$404:$J$417
Name BUNGBULANG: OLT!$J$346:$J$358
Name CARINGIN: OLT!$J$391:$J$396
Name CIBATU: OLT!$J$142:$J$152
Name CIBIUK: OLT!$J$425:$J$429
Name CIGEDUG: OLT!$J$216:$J$220
Name CIHURIP: OLT!$J$295:$J$298
Name CIKAJANG: OLT!$J$263:$J$274
Name CIKELET: OLT!$J$335:$J$345
Name CILAWU: OLT!$J$221:$J$238
Name CISEWU: OLT!$J$382:$J$390
Name CISOMPET: OLT!$J$313:$J$323
Name CISURUPAN: OLT!$J$239:$J$255
Name GARUT_KOTA: OLT!$J$3:$J$13
Name KADUNGORA: OLT!$J$120:$J$133
Name KARANGPAWITAN: OLT!$J$14:$J$33
Name KARANGTENGAH: OLT!$J$194:$J$197
Name KARYASARI: OLT!$J$324:$J$334
Name kecamatan: OLT!$I$3:$I$44
Name KERSAMANAH: OLT!$J$153:$J$158
Name LELES: OLT!$J$108:$J$119
Name LEUWIGOONG: OLT!$J$134:$J$141
Name MALANGBONG: OLT!$J$159:$J$182
Name MEKARMUKTI: OLT!$J$359:$J$363
Name PAKENJENG: OLT!$J$364:$J$376
Name PAMEUNGPEUK: OLT!$J$305:$J$312
Name PAMULIHAN: OLT!$J$377:$J$381
Name PANGATIKAN: OLT!$J$430:$J$437
Name PASIRWANGI: OLT!$J$96:$J$107
Name PEUNDEUY: OLT!$J$299:$J$304
Name SAMARANG: OLT!$J$83:$J$95
Name SELAAWI: OLT!$J$418:$J$424
Name SINGAJAYA: OLT!$J$286:$J$294
Name SUCINARAJA: OLT!$J$438:$J$444
Name SUKARESMI: OLT!$J$256:$J$262
Name SUKAWENING: OLT!$J$183:$J$193
Name TALEGONG: OLT!$J$397:$J$403
Name TAROGONG_KALER: OLT!$J$43:$J$55
Name TAROGONG_KIDUL: OLT!$J$56:$J$67
Name WANARAJA: OLT!$J$34:$J$42

Sheet HPDB FDT-1
A1: FIBER CORE ASSIGNMENT
A3: Region | C3: GARUT | L3: FDT TYPE | N3: 48 Core | P3: OLT CODE | Q3: =VLOOKUP('HPDB FDT-1'!$C$4,OLT!$A$2:$C$20,2,FALSE)
A4: OLT / Feeder Line | C4: OLT SAMARANG | L4: HP / Construction type | N4: =AJ8 | P4: OLT Hostname | Q4: =VLOOKUP('HPDB FDT-1'!$C$4,OLT!$A$2:$C$20,3,FALSE)
A5: Cluster Name | C5: Atavus aufero verto cibus astrum ipsum. | L5: Distance From OLT | N5: : XXX | P5: RFS DATE
A6: FDT ID | C6: Adficio complectus vinum minus claudeo facere concedo curatio dens pauci. | L6: COORDINATE FDT | M6: LATITUDE | N6: -7.3314997 | P6: SYMBOL WARNA | Q6: Curvo solium molestiae optio argentum comitatus ea.
A7: Cluster Code Astri | C7: Repudiandae dapifer amo canto. | M7: LONGTITUDE | N7: 107.80799 | P7: CYAN | Q7: WARNA CELL YANG BOLEH DIISI
AJ8: =COUNTA(AJ10:AJ337)
A9: FDT Tray (Front) | B9: FDT Port | C9: Line | D9: Capacity | E9: Tube Colour | F9: Core Number | G9: FAT ID | H9: FAT Port | I9: Pole ID | J9: Pole Latitude | K9: Pole Longitude | L9: FAT Address | M9: Province | N9: regency_city | O9: district | P9: subdistrict | Q9: postalcode | R9: Roll_Out_ID | S9: acquisition_class | T9: acquisition_tier | U9: competition | V9: project_id | W9: Area | X9: Complex_name | Y9: Clustername | Z9: Commercial_name | AA9: Rw | AB9: Rt | AC9: address_prefix | AD9: street | AE9: address_suffix | AF9: sub_address_prefix | AG9: sub_address | AH9: sub_address_suffix | AI9: block | AJ9: homenumber | AK9: dwelling_type | AL9: building_type | AM9: building_property_name | AN9: building_property_location | AO9: floor | AP9: unit | AQ9: homepass_source | AR9: oltcode | AS9: fdtcode | AT9: fatcode | AU9: RFSDate | AV9: Latitude_homepass | AW9: Longitude_homepass | AX9: residential_service_ready | AY9: sme_service_ready | AZ9: enterprise_service_ready | BA9: installation | BB9: availability | BC9: network_presence | BD9: wallplate_installation
A10: G1 | B10: 1 | C10: LINE A | D10: 48C/4T | E10: 1 | F10: 1 | G10: FAT A01 | H10: 1 | I10: MR.MGCTA01.P005 | J10: -7.12621511 | K10: 107.94037275 | M10: Succedo amissio labore coerceo. | N10: Cuius iure eos aperte tunc video tamdiu compono defaeco thesis. | O10: Aureus usus distinctio ulciscor benevolentia cruentus antea vomer vesica. | Y10: Repudiandae dapifer amo canto. | Z10: Repudiandae dapifer amo canto. | AJ10: NN-02 | AK10: Single Dwelling Unit
A11: G1 | B11: 1 | C11: LINE A | D11: 48C/4T | E11: 1 | F11: 1 | G11: FAT A01 | H11: 2 | I11: MR.MGCTA01.P005 | J11: -7.12621511 | K11: 107.94037275 | M11: Succedo amissio labore coerceo. | N11: Cuius iure eos aperte tunc video tamdiu compono defaeco thesis. | O11: Aureus usus distinctio ulciscor benevolentia cruentus antea vomer vesica. | Y11: Repudiandae dapifer amo canto. | Z11: Repudiandae dapifer amo canto. | AJ11: NN-03 | AK11: Single Dwelling Unit
A12: G1 | B12: 1 | C12: LINE A | D12: 48C/4T | E12: 1 | F12: 1 | G12: FAT A01 | H12: 3 | I12: MR.MGCTA01.P005 | J12: -7.12621511 | K12: 107.94037275 | M12: Succedo amissio labore coerceo. | N12: Cuius iure eos aperte tunc video tamdiu compono defaeco thesis. | O12: Aureus usus distinctio ulciscor benevolentia cruentus antea vomer vesica. | Y12: Repudiandae dapifer amo canto. | Z12: Repudiandae dapifer amo canto. | AJ12: NN-04 | AK12: Single Dwelling Unit
A13: G1 | B13: 1 | C13: LINE A | D13: 48C/4T | E13: 1 | F13: 1 | G13: FAT A01 | H13: 4 | I13: MR.MGCTA01.P005 | J13: -7.12621511 | K13: 107.94037275 | M13: Succedo amissio labore coerceo. | N13: Cuius iure eos aperte tunc video tamdiu compono defaeco thesis. | O13: Aureus usus distinctio ulciscor benevolentia cruentus antea vomer vesica. | Y13: Repudiandae dapifer amo canto. | Z13: Repudiandae dapifer amo canto. | AJ13: NN-05 | AK13: Single Dwelling Unit
A14: G1 | B14: 1 | C14: LINE A | D14: 48C/4T | E14: 1 | F14: 1 | G14: FAT A01 | H14: 5 | I14: MR.MGCTA01.P005 | J14: -7.12621511 | K14: 107.94037275 | M14: Succedo amissio labore coerceo. | N14: Cuius iure eos aperte tunc video tamdiu compono defaeco thesis. | O14: Aureus usus distinctio ulciscor benevolentia cruentus antea vomer vesica. | Y14: Repudiandae dapifer amo canto. | Z14: Repudiandae dapifer amo canto. | AJ14: NN-06 | AK14: Single Dwelling Unit
A15: G1 | B15: 1 | C15: LINE A | D15: 48C/4T | E15: 1 | F15: 1 | G15: FAT A01 | H15: 6 | I15: MR.MGCTA01.P005 | J15: -7.12621511 | K15: 107.94037275 | M15: Succedo amissio labore coerceo. | N15: Cuius iure eos aperte tunc video tamdiu compono defaeco thesis. | O15: Aureus usus distinctio ulciscor benevolentia cruentus antea vomer vesica. | Y15: Repudiandae dapifer amo canto. | Z15: Repudiandae dapifer amo canto. | AJ15: NN-07 | AK15: Single Dwelling Unit
A16: G1 | B16: 1 | C16: LINE A | D16: 48C/4T | E16: 1 | F16: 1 | G16: FAT A01 | H16: 7 | I16: MR.MGCTA01.P005 | J16: -7.12621511 | K16: 107.94037275 | M16: Succedo amissio labore coerceo. | N16: Cuius iure eos aperte tunc video tamdiu compono defaeco thesis. | O16: Aureus usus distinctio ulciscor benevolentia cruentus antea vomer vesica. | Y16: Repudiandae dapifer amo canto. | Z16: Repudiandae dapifer amo canto. | AJ16: NN-08 | AK16: Single Dwelling Unit
A17: G1 | B17: 1 | C17: LINE A | D17: 48C/4T | E17: 1 | F17: 1 | G17: FAT A01 | H17: 8 | I17: MR.MGCTA01.P005 | J17: -7.12621511 | K17: 107.94037275 | M17: Succedo amissio labore coerceo. | N17: Cuius iure eos aperte tunc video tamdiu compono defaeco thesis. | O17: Aureus usus distinctio ulciscor benevolentia cruentus antea vomer vesica. | Y17: Repudiandae dapifer amo canto. | Z17: Repudiandae dapifer amo canto. | AJ17: NN-09 | AK17: Single Dwelling Unit
A18: G1 | B18: 1 | C18: LINE A | D18: 48C/4T | E18: 1 | F18: 1 | G18: FAT A01 | H18: 9 | I18: MR.MGCTA01.P005 | J18: -7.12621511 | K18: 107.94037275 | M18: Succedo amissio labore coerceo. | N18: Cuius iure eos aperte tunc video tamdiu compono defaeco thesis. | O18: Aureus usus distinctio ulciscor benevolentia cruentus antea vomer vesica. | Y18: Repudiandae dapifer amo canto. | Z18: Repudiandae dapifer amo canto. | AJ18: NN-10 | AK18: Single Dwelling Unit
A19: G1 | B19: 1 | C19: LINE A | D19: 48C/4T | E19: 1 | F19: 1 | G19: FAT A01 | H19: 10 | I19: MR.MGCTA01.P005 | J19: -7.12621511 | K19: 107.94037275 | M19: Succedo amissio labore coerceo. | N19: Cuius iure eos aperte tunc video tamdiu compono defaeco thesis. | O19: Aureus usus distinctio ulciscor benevolentia cruentus antea vomer vesica. | Y19: Repudiandae dapifer amo canto. | Z19: Repudiandae dapifer amo canto. | AJ19: NN-11 | AK19: Single Dwelling Unit
A20: G1 | B20: 1 | C20: LINE A | D20: 48C/4T | E20: 1 | F20: 1 | G20: FAT A01 | H20: 11 | I20: MR.MGCTA01.P005 | J20: -7.12621511 | K20: 107.94037275 | M20: Succedo amissio labore coerceo. | N20: Cuius iure eos aperte tunc video tamdiu compono defaeco thesis. | O20: Aureus usus distinctio ulciscor benevolentia cruentus antea vomer vesica. | Y20: Repudiandae dapifer amo canto. | Z20: Repudiandae dapifer amo canto. | AJ20: NN-12 | AK20: Single Dwelling Unit
A21: G1 | B21: 1 | C21: LINE A | D21: 48C/4T | E21: 1 | F21: 1 | G21: FAT A01 | H21: 12 | I21: MR.MGCTA01.P005 | J21: -7.12621511 | K21: 107.94037275 | M21: Succedo amissio labore coerceo. | N21: Cuius iure eos aperte tunc video tamdiu compono defaeco thesis. | O21: Aureus usus distinctio ulciscor benevolentia cruentus antea vomer vesica. | Y21: Repudiandae dapifer amo canto. | Z21: Repudiandae dapifer amo canto. | AJ21: NN-13 | AK21: Single Dwelling Unit
... A144: G1 | B144: 1 | C144: LINE B | D144: 48C/4T | E144: 1 | F144: 11 | G144: FAT B05 | H144: 8 | I144: MR.MGCTA01.P032 | J144: -7.126122290000001 | K144: 107.94092227 | M144: Succedo amissio labore coerceo. | N144: Cuius iure eos aperte tunc video tamdiu compono defaeco thesis. | O144: Aureus usus distinctio ulciscor benevolentia cruentus antea vomer vesica. | Y144: Repudiandae dapifer amo canto. | Z144: Repudiandae dapifer amo canto. | AJ144: NN-72 | AK144: Single Dwelling Unit

Sheet FAT HPDB FDT-1
A1: LABEL | B1: LATITUDE | C1: LONGITUDE | D1: POLE ID | F1: Catatan : FAT yang tidak diperlukan harap di hapus saja datanya jangan di Delete Cell
A2: A01 | B2: 1 | C2: 2 | D2: MR.XXX.P001
A3: A02 | B3: 3 | C3: 4 | D3: MR.XXX.P002
A4: A03 | B4: 5 | C4: 6 | D4: MR.XXX.P003
A5: A04 | B5: 7 | C5: 8 | D5: MR.XXX.P004
A6: A05 | B6: 9 | C6: 10 | D6: MR.XXX.P005
A7: A06 | B7: 11 | C7: 12 | D7: MR.XXX.P006
A8: A07 | B8: 13 | C8: 14 | D8: MR.XXX.P007
A9: A08 | B9: 15 | C9: 16 | D9: MR.XXX.P008
A10: A09 | B10: 17 | C10: 18 | D10: MR.XXX.P009
A11: A10 | B11: 19 | C11: 20 | D11: MR.XXX.P010
A12: A11 | B12: 21 | C12: 22 | D12: MR.XXX.P011
A13: A12 | B13: 23 | C13: 24 | D13: MR.XXX.P012
... A41: B20 | B41: 79 | C41: 80 | D41: MR.XXX.P040

Sheet CLUSTER FDT-1
A1: cluster_name | B1: fdt_code | C1: commercial_name | D1: province | E1: competition | F1: city | G1: area_name | H1: rfs_date | I1: district | J1: acquisition_class | K1: acquisition_tier | L1: postal_code | M1: sub_district | N1: olt_code | O1: cluster_type | P1: complex | Q1: project_name | R1: project_id | S1: latitude_cluster | T1: longitude_cluster | U1: cluster_code_astri
A2: =IF('HPDB FDT-1'!$Y$10="","",'HPDB FDT-1'!$Y$10) | B2: =IF('HPDB FDT-1'!$C$6="","",'HPDB FDT-1'!$C$6) | C2: =IF($A$2="","",$A$2) | D2: =PROPER(IF('HPDB FDT-1'!$M$10="","",'HPDB FDT-1'!$M$10)) | E2: FTTH | F2: Kab. Garut | G2: Garut | H2: =IF('HPDB FDT-1'!$AU$10="","",'HPDB FDT-1'!$AU$10) | I2: =PROPER(IF('HPDB FDT-1'!$O$10="","",'HPDB FDT-1'!$O$10)) | J2: =IF('HPDB FDT-1'!$S$10="","",'HPDB FDT-1'!$S$10) | K2: =IF('HPDB FDT-1'!$T$10="","",'HPDB FDT-1'!$T$10) | L2: =IF('HPDB FDT-1'!$Q$10="","",'HPDB FDT-1'!$Q$10) | M2: =PROPER(IF('HPDB FDT-1'!$P$10="","",'HPDB FDT-1'!$P$10)) | N2: =IF('HPDB FDT-1'!$Q$3="","",'HPDB FDT-1'!$Q$3) | O2: Onnet | P2: =IF($A$2="","",$A$2) | Q2: General Retail | R2: =IF('HPDB FDT-1'!$V$10="","",'HPDB FDT-1'!$V$10) | S2: =IF('HPDB FDT-1'!$N$6="","",'HPDB FDT-1'!$N$6) | T2: =IF('HPDB FDT-1'!$N$7="","",'HPDB FDT-1'!$N$7) | U2: =IF('HPDB FDT-1'!$C$7="","",'HPDB FDT-1'!$C$7)

Sheet FAT FDT-1
A1: Area | B1: Clustername | C1: FAT Code | D1: FDT Code | E1: Port Count
A2: =IF($C2<>"","GARUT","") | B2: =IF($C2<>"",'CLUSTER FDT-1'!$A$2,"") | C2: =IF('FAT HPDB FDT-1'!$A2="","",'FAT HPDB FDT-1'!$A2) | D2: =IF($A2<>"",'HPDB FDT-1'!$C$6,"") | E2: =IF($A2<>"","16","")
A3: =IF($C3<>"","GARUT","") | B3: =IF($C3<>"",'CLUSTER FDT-1'!$A$2,"") | C3: =IF('FAT HPDB FDT-1'!$A3="","",'FAT HPDB FDT-1'!$A3) | D3: =IF($A3<>"",'HPDB FDT-1'!$C$6,"") | E3: =IF($A3<>"","16","")
A4: =IF($C4<>"","GARUT","") | B4: =IF($C4<>"",'CLUSTER FDT-1'!$A$2,"") | C4: =IF('FAT HPDB FDT-1'!$A4="","",'FAT HPDB FDT-1'!$A4) | D4: =IF($A4<>"",'HPDB FDT-1'!$C$6,"") | E4: =IF($A4<>"","16","")
A5: =IF($C5<>"","GARUT","") | B5: =IF($C5<>"",'CLUSTER FDT-1'!$A$2,"") | C5: =IF('FAT HPDB FDT-1'!$A5="","",'FAT HPDB FDT-1'!$A5) | D5: =IF($A5<>"",'HPDB FDT-1'!$C$6,"") | E5: =IF($A5<>"","16","")
A6: =IF($C6<>"","GARUT","") | B6: =IF($C6<>"",'CLUSTER FDT-1'!$A$2,"") | C6: =IF('FAT HPDB FDT-1'!$A6="","",'FAT HPDB FDT-1'!$A6) | D6: =IF($A6<>"",'HPDB FDT-1'!$C$6,"") | E6: =IF($A6<>"","16","")
A7: =IF($C7<>"","GARUT","") | B7: =IF($C7<>"",'CLUSTER FDT-1'!$A$2,"") | C7: =IF('FAT HPDB FDT-1'!$A7="","",'FAT HPDB FDT-1'!$A7) | D7: =IF($A7<>"",'HPDB FDT-1'!$C$6,"") | E7: =IF($A7<>"","16","")
A8: =IF($C8<>"","GARUT","") | B8: =IF($C8<>"",'CLUSTER FDT-1'!$A$2,"") | C8: =IF('FAT HPDB FDT-1'!$A8="","",'FAT HPDB FDT-1'!$A8) | D8: =IF($A8<>"",'HPDB FDT-1'!$C$6,"") | E8: =IF($A8<>"","16","")
A9: =IF($C9<>"","GARUT","") | B9: =IF($C9<>"",'CLUSTER FDT-1'!$A$2,"") | C9: =IF('FAT HPDB FDT-1'!$A9="","",'FAT HPDB FDT-1'!$A9) | D9: =IF($A9<>"",'HPDB FDT-1'!$C$6,"") | E9: =IF($A9<>"","16","")
A10: =IF($C10<>"","GARUT","") | B10: =IF($C10<>"",'CLUSTER FDT-1'!$A$2,"") | C10: =IF('FAT HPDB FDT-1'!$A10="","",'FAT HPDB FDT-1'!$A10) | D10: =IF($A10<>"",'HPDB FDT-1'!$C$6,"") | E10: =IF($A10<>"","16","")
A11: =IF($C11<>"","GARUT","") | B11: =IF($C11<>"",'CLUSTER FDT-1'!$A$2,"") | C11: =IF('FAT HPDB FDT-1'!$A11="","",'FAT HPDB FDT-1'!$A11) | D11: =IF($A11<>"",'HPDB FDT-1'!$C$6,"") | E11: =IF($A11<>"","16","")
A12: =IF($C12<>"","GARUT","") | B12: =IF($C12<>"",'CLUSTER FDT-1'!$A$2,"") | C12: =IF('FAT HPDB FDT-1'!$A12="","",'FAT HPDB FDT-1'!$A12) | D12: =IF($A12<>"",'HPDB FDT-1'!$C$6,"") | E12: =IF($A12<>"","16","")
A13: =IF($C13<>"","GARUT","") | B13: =IF($C13<>"",'CLUSTER FDT-1'!$A$2,"") | C13: =IF('FAT HPDB FDT-1'!$A13="","",'FAT HPDB FDT-1'!$A13) | D13: =IF($A13<>"",'HPDB FDT-1'!$C$6,"") | E13: =IF($A13<>"","16","")
... A100: =IF($C100<>"","GARUT","") | B100: =IF($C100<>"",'CLUSTER FDT-1'!$A$2,"") | C100: =IF('FAT HPDB FDT-1'!$A100="","",'FAT HPDB FDT-1'!$A100) | D100: =IF($A100<>"",'HPDB FDT-1'!$C$6,"") | E100: =IF($A100<>"","16","")

Sheet HOMEPASS FDT-1
A1: postalcode | B1: Roll_Out_ID | C1: acquisition_class | D1: acquisition_tier | E1: competition | F1: project_id | G1: projectName | H1: Complex_name | I1: ClusterId | J1: Clustername | K1: Commercial_name | L1: Rw | M1: Rt | N1: address_prefix | O1: street | P1: address_suffix | Q1: sub_address_prefix | R1: sub_address | S1: sub_address_suffix | T1: block | U1: homenumber | V1: dwelling_type | W1: building_type | X1: building_property_name | Y1: building_property_location | Z1: floor | AA1: unit | AB1: homepass_source | AC1: oltcode | AD1: olthostname | AE1: fdtcode | AF1: fatcode | AG1: RFSDate | AH1: Latitude_homepass | AI1: Longitude_homepass | AJ1: vendor_homepass_id | AK1: residential_service_ready | AL1: sme_service_ready | AM1: enterprise_service_ready | AN1: installation | AO1: availability | AP1: classification | AQ1: business_case | AR1: network_presence | AS1: wallplate_installation | AT1: publish
A2: =IF($U2<>"",'HPDB FDT-1'!$Q10,"") | B2: =IF($U2<>"",'HPDB FDT-1'!$R10,"") | C2: =IF($U2<>"",'HPDB FDT-1'!$S10,"") | D2: =IF($U2<>"",'HPDB FDT-1'!$T10,"") | E2: =IF($U2<>"","FTTH","") | F2: =IF($U2<>"",'HPDB FDT-1'!$V10,"") | G2: =IF($U2<>"","General Retail","") | H2: =IF($U2<>"",'CLUSTER FDT-1'!$A$2,"") | J2: =IF($U2<>"",'CLUSTER FDT-1'!$A$2,"") | K2: =IF($U2<>"",'CLUSTER FDT-1'!$A$2,"") | L2: =IF($U2<>"",'HPDB FDT-1'!$AA10,"") | M2: =IF($U2<>"",'HPDB FDT-1'!$AB10,"") | N2: =IF($U2<>"",'HPDB FDT-1'!$AC10,"") | O2: =IF('HPDB FDT-1'!$AD10="","",'HPDB FDT-1'!$AD10) | T2: =IF('HPDB FDT-1'!$AI10="","",'HPDB FDT-1'!$AI10) | U2: =IF('HPDB FDT-1'!$AJ10="","",'HPDB FDT-1'!$AJ10) | V2: =IF($U2<>"","Single Dwelling Unit","") | W2: j | AB2: =IF($U2<>"","RFS","") | AC2: =IF($U2<>"",'HPDB FDT-1'!$Q$3,"") | AD2: =IF($U2<>"",'HPDB FDT-1'!$Q$4,"") | AE2: =IF($U2<>"",'HPDB FDT-1'!$C$6,"") | AF2: =IF($U2<>"",'HPDB FDT-1'!$AT10,"") | AG2: =IF($A2<>"",'CLUSTER FDT-1'!$H$2,"") | AH2: =IF('HPDB FDT-1'!$AV10="","",'HPDB FDT-1'!$AV10) | AI2: =IF('HPDB FDT-1'!$AW10="","",'HPDB FDT-1'!$AW10) | AK2: =IF($U2<>"",'HPDB FDT-1'!$AX10,"") | AL2: =IF($U2<>"",'HPDB FDT-1'!$AY10,"") | AM2: =IF($U2<>"",'HPDB FDT-1'!$AZ10,"") | AN2: =IF($U2<>"",'HPDB FDT-1'!$BA10,"") | AO2: =IF($U2<>"",'HPDB FDT-1'!$BB10,"") | AP2: =IF($U2<>"","RFS","") | AR2: =IF($U2<>"","31","") | AS2: =IF($U2<>"","FALSE","") | AT2: =IF($U2<>"","TRUE","")
A3: =IF($U3<>"",'HPDB FDT-1'!$Q11,"") | B3: =IF($U3<>"",'HPDB FDT-1'!$R11,"") | C3: =IF($U3<>"",'HPDB FDT-1'!$S11,"") | D3: =IF($U3<>"",'HPDB FDT-1'!$T11,"") | E3: =IF($U3<>"","FTTH","") | F3: =IF($U3<>"",'HPDB FDT-1'!$V11,"") | G3: =IF($U3<>"","General Retail","") | H3: =IF($U3<>"",'CLUSTER FDT-1'!$A$2,"") | J3: =IF($U3<>"",'CLUSTER FDT-1'!$A$2,"") | K3: =IF($U3<>"",'CLUSTER FDT-1'!$A$2,"") | L3: =IF($U3<>"",'HPDB FDT-1'!$AA11,"") | M3: =IF($U3<>"",'HPDB FDT-1'!$AB11,"") | N3: =IF($U3<>"",'HPDB FDT-1'!$AC11,"") | O3: =IF('HPDB FDT-1'!$AD11="","",'HPDB FDT-1'!$AD11) | T3: =IF('HPDB FDT-1'!$AI11="","",'HPDB FDT-1'!$AI11) | U3: =IF('HPDB FDT-1'!$AJ11="","",'HPDB FDT-1'!$AJ11) | V3: =IF($U3<>"","Single Dwelling Unit","") | AB3: =IF($U3<>"","RFS","") | AC3: =IF($U3<>"",'HPDB FDT-1'!$Q$3,"") | AD3: =IF($U3<>"",'HPDB FDT-1'!$Q$4,"") | AE3: =IF($U3<>"",'HPDB FDT-1'!$C$6,"") | AF3: =IF($U3<>"",'HPDB FDT-1'!$AT11,"") | AG3: =IF($A3<>"",'CLUSTER FDT-1'!$H$2,"") | AH3: =IF('HPDB FDT-1'!$AV11="","",'HPDB FDT-1'!$AV11) | AI3: =IF('HPDB FDT-1'!$AW11="","",'HPDB FDT-1'!$AW11) | AK3: =IF($U3<>"",'HPDB FDT-1'!$AX11,"") | AL3: =IF($U3<>"",'HPDB FDT-1'!$AY11,"") | AM3: =IF($U3<>"",'HPDB FDT-1'!$AZ11,"") | AN3: =IF($U3<>"",'HPDB FDT-1'!$BA11,"") | AO3: =IF($U3<>"",'HPDB FDT-1'!$BB11,"") | AP3: =IF($U3<>"","RFS","") | AR3: =IF($U3<>"","31","") | AS3: =IF($U3<>"","FALSE","") | AT3: =IF($U3<>"","TRUE","")
A4: =IF($U4<>"",'HPDB FDT-1'!$Q12,"") | B4: =IF($U4<>"",'HPDB FDT-1'!$R12,"") | C4: =IF($U4<>"",'HPDB FDT-1'!$S12,"") | D4: =IF($U4<>"",'HPDB FDT-1'!$T12,"") | E4: =IF($U4<>"","FTTH","") | F4: =IF($U4<>"",'HPDB FDT-1'!$V12,"") | G4: =IF($U4<>"","General Retail","") | H4: =IF($U4<>"",'CLUSTER FDT-1'!$A$2,"") | J4: =IF($U4<>"",'CLUSTER FDT-1'!$A$2,"") | K4: =IF($U4<>"",'CLUSTER FDT-1'!$A$2,"") | L4: =IF($U4<>"",'HPDB FDT-1'!$AA12,"") | M4: =IF($U4<>"",'HPDB FDT-1'!$AB12,"") | N4: =IF($U4<>"",'HPDB FDT-1'!$AC12,"") | O4: =IF('HPDB FDT-1'!$AD12="","",'HPDB FDT-1'!$AD12) | T4: =IF('HPDB FDT-1'!$AI12="","",'HPDB FDT-1'!$AI12) | U4: =IF('HPDB FDT-1'!$AJ12="","",'HPDB FDT-1'!$AJ12) | V4: =IF($U4<>"","Single Dwelling Unit","") | AB4: =IF($U4<>"","RFS","") | AC4: =IF($U4<>"",'HPDB FDT-1'!$Q$3,"") | AD4: =IF($U4<>"",'HPDB FDT-1'!$Q$4,"") | AE4: =IF($U4<>"",'HPDB FDT-1'!$C$6,"") | AF4: =IF($U4<>"",'HPDB FDT-1'!$AT12,"") | AG4: =IF($A4<>"",'CLUSTER FDT-1'!$H$2,"") | AH4: =IF('HPDB FDT-1'!$AV12="","",'HPDB FDT-1'!$AV12) | AI4: =IF('HPDB FDT-1'!$AW12="","",'HPDB FDT-1'!$AW12) | AK4: =IF($U4<>"",'HPDB FDT-1'!$AX12,"") | AL4: =IF($U4<>"",'HPDB FDT-1'!$AY12,"") | AM4: =IF($U4<>"",'HPDB FDT-1'!$AZ12,"") | AN4: =IF($U4<>"",'HPDB FDT-1'!$BA12,"") | AO4: =IF($U4<>"",'HPDB FDT-1'!$BB12,"") | AP4: =IF($U4<>"","RFS","") | AR4: =IF($U4<>"","31","") | AS4: =IF($U4<>"","FALSE","") | AT4: =IF($U4<>"","TRUE","")
A5: =IF($U5<>"",'HPDB FDT-1'!$Q13,"") | B5: =IF($U5<>"",'HPDB FDT-1'!$R13,"") | C5: =IF($U5<>"",'HPDB FDT-1'!$S13,"") | D5: =IF($U5<>"",'HPDB FDT-1'!$T13,"") | E5: =IF($U5<>"","FTTH","") | F5: =IF($U5<>"",'HPDB FDT-1'!$V13,"") | G5: =IF($U5<>"","General Retail","") | H5: =IF($U5<>"",'CLUSTER FDT-1'!$A$2,"") | J5: =IF($U5<>"",'CLUSTER FDT-1'!$A$2,"") | K5: =IF($U5<>"",'CLUSTER FDT-1'!$A$2,"") | L5: =IF($U5<>"",'HPDB FDT-1'!$AA13,"") | M5: =IF($U5<>"",'HPDB FDT-1'!$AB13,"") | N5: =IF($U5<>"",'HPDB FDT-1'!$AC13,"") | O5: =IF('HPDB FDT-1'!$AD13="","",'HPDB FDT-1'!$AD13) | T5: =IF('HPDB FDT-1'!$AI13="","",'HPDB FDT-1'!$AI13) | U5: =IF('HPDB FDT-1'!$AJ13="","",'HPDB FDT-1'!$AJ13) | V5: =IF($U5<>"","Single Dwelling Unit","") | AB5: =IF($U5<>"","RFS","") | AC5: =IF($U5<>"",'HPDB FDT-1'!$Q$3,"") | AD5: =IF($U5<>"",'HPDB FDT-1'!$Q$4,"") | AE5: =IF($U5<>"",'HPDB FDT-1'!$C$6,"") | AF5: =IF($U5<>"",'HPDB FDT-1'!$AT13,"") | AG5: =IF($A5<>"",'CLUSTER FDT-1'!$H$2,"") | AH5: =IF('HPDB FDT-1'!$AV13="","",'HPDB FDT-1'!$AV13) | AI5: =IF('HPDB FDT-1'!$AW13="","",'HPDB FDT-1'!$AW13) | AK5: =IF($U5<>"",'HPDB FDT-1'!$AX13,"") | AL5: =IF($U5<>"",'HPDB FDT-1'!$AY13,"") | AM5: =IF($U5<>"",'HPDB FDT-1'!$AZ13,"") | AN5: =IF($U5<>"",'HPDB FDT-1'!$BA13,"") | AO5: =IF($U5<>"",'HPDB FDT-1'!$BB13,"") | AP5: =IF($U5<>"","RFS","") | AR5: =IF($U5<>"","31","") | AS5: =IF($U5<>"","FALSE","") | AT5: =IF($U5<>"","TRUE","")
A6: =IF($U6<>"",'HPDB FDT-1'!$Q14,"") | B6: =IF($U6<>"",'HPDB FDT-1'!$R14,"") | C6: =IF($U6<>"",'HPDB FDT-1'!$S14,"") | D6: =IF($U6<>"",'HPDB FDT-1'!$T14,"") | E6: =IF($U6<>"","FTTH","") | F6: =IF($U6<>"",'HPDB FDT-1'!$V14,"") | G6: =IF($U6<>"","General Retail","") | H6: =IF($U6<>"",'CLUSTER FDT-1'!$A$2,"") | J6: =IF($U6<>"",'CLUSTER FDT-1'!$A$2,"") | K6: =IF($U6<>"",'CLUSTER FDT-1'!$A$2,"") | L6: =IF($U6<>"",'HPDB FDT-1'!$AA14,"") | M6: =IF($U6<>"",'HPDB FDT-1'!$AB14,"") | N6: =IF($U6<>"",'HPDB FDT-1'!$AC14,"") | O6: =IF('HPDB FDT-1'!$AD14="","",'HPDB FDT-1'!$AD14) | T6: =IF('HPDB FDT-1'!$AI14="","",'HPDB FDT-1'!$AI14) | U6: =IF('HPDB FDT-1'!$AJ14="","",'HPDB FDT-1'!$AJ14) | V6: =IF($U6<>"","Single Dwelling Unit","") | AB6: =IF($U6<>"","RFS","") | AC6: =IF($U6<>"",'HPDB FDT-1'!$Q$3,"") | AD6: =IF($U6<>"",'HPDB FDT-1'!$Q$4,"") | AE6: =IF($U6<>"",'HPDB FDT-1'!$C$6,"") | AF6: =IF($U6<>"",'HPDB FDT-1'!$AT14,"") | AG6: =IF($A6<>"",'CLUSTER FDT-1'!$H$2,"") | AH6: =IF('HPDB FDT-1'!$AV14="","",'HPDB FDT-1'!$AV14) | AI6: =IF('HPDB FDT-1'!$AW14="","",'HPDB FDT-1'!$AW14) | AK6: =IF($U6<>"",'HPDB FDT-1'!$AX14,"") | AL6: =IF($U6<>"",'HPDB FDT-1'!$AY14,"") | AM6: =IF($U6<>"",'HPDB FDT-1'!$AZ14,"") | AN6: =IF($U6<>"",'HPDB FDT-1'!$BA14,"") | AO6: =IF($U6<>"",'HPDB FDT-1'!$BB14,"") | AP6: =IF($U6<>"","RFS","") | AR6: =IF($U6<>"","31","") | AS6: =IF($U6<>"","FALSE","") | AT6: =IF($U6<>"","TRUE","")
A7: =IF($U7<>"",'HPDB FDT-1'!$Q15,"") | B7: =IF($U7<>"",'HPDB FDT-1'!$R15,"") | C7: =IF($U7<>"",'HPDB FDT-1'!$S15,"") | D7: =IF($U7<>"",'HPDB FDT-1'!$T15,"") | E7: =IF($U7<>"","FTTH","") | F7: =IF($U7<>"",'HPDB FDT-1'!$V15,"") | G7: =IF($U7<>"","General Retail","") | H7: =IF($U7<>"",'CLUSTER FDT-1'!$A$2,"") | J7: =IF($U7<>"",'CLUSTER FDT-1'!$A$2,"") | K7: =IF($U7<>"",'CLUSTER FDT-1'!$A$2,"") | L7: =IF($U7<>"",'HPDB FDT-1'!$AA15,"") | M7: =IF($U7<>"",'HPDB FDT-1'!$AB15,"") | N7: =IF($U7<>"",'HPDB FDT-1'!$AC15,"") | O7: =IF('HPDB FDT-1'!$AD15="","",'HPDB FDT-1'!$AD15) | T7: =IF('HPDB FDT-1'!$AI15="","",'HPDB FDT-1'!$AI15) | U7: =IF('HPDB FDT-1'!$AJ15="","",'HPDB FDT-1'!$AJ15) | V7: =IF($U7<>"","Single Dwelling Unit","") | AB7: =IF($U7<>"","RFS","") | AC7: =IF($U7<>"",'HPDB FDT-1'!$Q$3,"") | AD7: =IF($U7<>"",'HPDB FDT-1'!$Q$4,"") | AE7: =IF($U7<>"",'HPDB FDT-1'!$C$6,"") | AF7: =IF($U7<>"",'HPDB FDT-1'!$AT15,"") | AG7: =IF($A7<>"",'CLUSTER FDT-1'!$H$2,"") | AH7: =IF('HPDB FDT-1'!$AV15="","",'HPDB FDT-1'!$AV15) | AI7: =IF('HPDB FDT-1'!$AW15="","",'HPDB FDT-1'!$AW15) | AK7: =IF($U7<>"",'HPDB FDT-1'!$AX15,"") | AL7: =IF($U7<>"",'HPDB FDT-1'!$AY15,"") | AM7: =IF($U7<>"",'HPDB FDT-1'!$AZ15,"") | AN7: =IF($U7<>"",'HPDB FDT-1'!$BA15,"") | AO7: =IF($U7<>"",'HPDB FDT-1'!$BB15,"") | AP7: =IF($U7<>"","RFS","") | AR7: =IF($U7<>"","31","") | AS7: =IF($U7<>"","FALSE","") | AT7: =IF($U7<>"","TRUE","")
A8: =IF($U8<>"",'HPDB FDT-1'!$Q16,"") | B8: =IF($U8<>"",'HPDB FDT-1'!$R16,"") | C8: =IF($U8<>"",'HPDB FDT-1'!$S16,"") | D8: =IF($U8<>"",'HPDB FDT-1'!$T16,"") | E8: =IF($U8<>"","FTTH","") | F8: =IF($U8<>"",'HPDB FDT-1'!$V16,"") | G8: =IF($U8<>"","General Retail","") | H8: =IF($U8<>"",'CLUSTER FDT-1'!$A$2,"") | J8: =IF($U8<>"",'CLUSTER FDT-1'!$A$2,"") | K8: =IF($U8<>"",'CLUSTER FDT-1'!$A$2,"") | L8: =IF($U8<>"",'HPDB FDT-1'!$AA16,"") | M8: =IF($U8<>"",'HPDB FDT-1'!$AB16,"") | N8: =IF($U8<>"",'HPDB FDT-1'!$AC16,"") | O8: =IF('HPDB FDT-1'!$AD16="","",'HPDB FDT-1'!$AD16) | T8: =IF('HPDB FDT-1'!$AI16="","",'HPDB FDT-1'!$AI16) | U8: =IF('HPDB FDT-1'!$AJ16="","",'HPDB FDT-1'!$AJ16) | V8: =IF($U8<>"","Single Dwelling Unit","") | AB8: =IF($U8<>"","RFS","") | AC8: =IF($U8<>"",'HPDB FDT-1'!$Q$3,"") | AD8: =IF($U8<>"",'HPDB FDT-1'!$Q$4,"") | AE8: =IF($U8<>"",'HPDB FDT-1'!$C$6,"") | AF8: =IF($U8<>"",'HPDB FDT-1'!$AT16,"") | AG8: =IF($A8<>"",'CLUSTER FDT-1'!$H$2,"") | AH8: =IF('HPDB FDT-1'!$AV16="","",'HPDB FDT-1'!$AV16) | AI8: =IF('HPDB FDT-1'!$AW16="","",'HPDB FDT-1'!$AW16) | AK8: =IF($U8<>"",'HPDB FDT-1'!$AX16,"") | AL8: =IF($U8<>"",'HPDB FDT-1'!$AY16,"") | AM8: =IF($U8<>"",'HPDB FDT-1'!$AZ16,"") | AN8: =IF($U8<>"",'HPDB FDT-1'!$BA16,"") | AO8: =IF($U8<>"",'HPDB FDT-1'!$BB16,"") | AP8: =IF($U8<>"","RFS","") | AR8: =IF($U8<>"","31","") | AS8: =IF($U8<>"","FALSE","") | AT8: =IF($U8<>"","TRUE","")
A9: =IF($U9<>"",'HPDB FDT-1'!$Q17,"") | B9: =IF($U9<>"",'HPDB FDT-1'!$R17,"") | C9: =IF($U9<>"",'HPDB FDT-1'!$S17,"") | D9: =IF($U9<>"",'HPDB FDT-1'!$T17,"") | E9: =IF($U9<>"","FTTH","") | F9: =IF($U9<>"",'HPDB FDT-1'!$V17,"") | G9: =IF($U9<>"","General Retail","") | H9: =IF($U9<>"",'CLUSTER FDT-1'!$A$2,"") | J9: =IF($U9<>"",'CLUSTER FDT-1'!$A$2,"") | K9: =IF($U9<>"",'CLUSTER FDT-1'!$A$2,"") | L9: =IF($U9<>"",'HPDB FDT-1'!$AA17,"") | M9: =IF($U9<>"",'HPDB FDT-1'!$AB17,"") | N9: =IF($U9<>"",'HPDB FDT-1'!$AC17,"") | O9: =IF('HPDB FDT-1'!$AD17="","",'HPDB FDT-1'!$AD17) | T9: =IF('HPDB FDT-1'!$AI17="","",'HPDB FDT-1'!$AI17) | U9: =IF('HPDB FDT-1'!$AJ17="","",'HPDB FDT-1'!$AJ17) | V9: =IF($U9<>"","Single Dwelling Unit","") | AB9: =IF($U9<>"","RFS","") | AC9: =IF($U9<>"",'HPDB FDT-1'!$Q$3,"") | AD9: =IF($U9<>"",'HPDB FDT-1'!$Q$4,"") | AE9: =IF($U9<>"",'HPDB FDT-1'!$C$6,"") | AF9: =IF($U9<>"",'HPDB FDT-1'!$AT17,"") | AG9: =IF($A9<>"",'CLUSTER FDT-1'!$H$2,"") | AH9: =IF('HPDB FDT-1'!$AV17="","",'HPDB FDT-1'!$AV17) | AI9: =IF('HPDB FDT-1'!$AW17="","",'HPDB FDT-1'!$AW17) | AK9: =IF($U9<>"",'HPDB FDT-1'!$AX17,"") | AL9: =IF($U9<>"",'HPDB FDT-1'!$AY17,"") | AM9: =IF($U9<>"",'HPDB FDT-1'!$AZ17,"") | AN9: =IF($U9<>"",'HPDB FDT-1'!$BA17,"") | AO9: =IF($U9<>"",'HPDB FDT-1'!$BB17,"") | AP9: =IF($U9<>"","RFS","") | AR9: =IF($U9<>"","31","") | AS9: =IF($U9<>"","FALSE","") | AT9: =IF($U9<>"","TRUE","")
A10: =IF($U10<>"",'HPDB FDT-1'!$Q18,"") | B10: =IF($U10<>"",'HPDB FDT-1'!$R18,"") | C10: =IF($U10<>"",'HPDB FDT-1'!$S18,"") | D10: =IF($U10<>"",'HPDB FDT-1'!$T18,"") | E10: =IF($U10<>"","FTTH","") | F10: =IF($U10<>"",'HPDB FDT-1'!$V18,"") | G10: =IF($U10<>"","General Retail","") | H10: =IF($U10<>"",'CLUSTER FDT-1'!$A$2,"") | J10: =IF($U10<>"",'CLUSTER FDT-1'!$A$2,"") | K10: =IF($U10<>"",'CLUSTER FDT-1'!$A$2,"") | L10: =IF($U10<>"",'HPDB FDT-1'!$AA18,"") | M10: =IF($U10<>"",'HPDB FDT-1'!$AB18,"") | N10: =IF($U10<>"",'HPDB FDT-1'!$AC18,"") | O10: =IF('HPDB FDT-1'!$AD18="","",'HPDB FDT-1'!$AD18) | T10: =IF('HPDB FDT-1'!$AI18="","",'HPDB FDT-1'!$AI18) | U10: =IF('HPDB FDT-1'!$AJ18="","",'HPDB FDT-1'!$AJ18) | V10: =IF($U10<>"","Single Dwelling Unit","") | AB10: =IF($U10<>"","RFS","") | AC10: =IF($U10<>"",'HPDB FDT-1'!$Q$3,"") | AD10: =IF($U10<>"",'HPDB FDT-1'!$Q$4,"") | AE10: =IF($U10<>"",'HPDB FDT-1'!$C$6,"") | AF10: =IF($U10<>"",'HPDB FDT-1'!$AT18,"") | AG10: =IF($A10<>"",'CLUSTER FDT-1'!$H$2,"") | AH10: =IF('HPDB FDT-1'!$AV18="","",'HPDB FDT-1'!$AV18) | AI10: =IF('HPDB FDT-1'!$AW18="","",'HPDB FDT-1'!$AW18) | AK10: =IF($U10<>"",'HPDB FDT-1'!$AX18,"") | AL10: =IF($U10<>"",'HPDB FDT-1'!$AY18,"") | AM10: =IF($U10<>"",'HPDB FDT-1'!$AZ18,"") | AN10: =IF($U10<>"",'HPDB FDT-1'!$BA18,"") | AO10: =IF($U10<>"",'HPDB FDT-1'!$BB18,"") | AP10: =IF($U10<>"","RFS","") | AR10: =IF($U10<>"","31","") | AS10: =IF($U10<>"","FALSE","") | AT10: =IF($U10<>"","TRUE","")
A11: =IF($U11<>"",'HPDB FDT-1'!$Q19,"") | B11: =IF($U11<>"",'HPDB FDT-1'!$R19,"") | C11: =IF($U11<>"",'HPDB FDT-1'!$S19,"") | D11: =IF($U11<>"",'HPDB FDT-1'!$T19,"") | E11: =IF($U11<>"","FTTH","") | F11: =IF($U11<>"",'HPDB FDT-1'!$V19,"") | G11: =IF($U11<>"","General Retail","") | H11: =IF($U11<>"",'CLUSTER FDT-1'!$A$2,"") | J11: =IF($U11<>"",'CLUSTER FDT-1'!$A$2,"") | K11: =IF($U11<>"",'CLUSTER FDT-1'!$A$2,"") | L11: =IF($U11<>"",'HPDB FDT-1'!$AA19,"") | M11: =IF($U11<>"",'HPDB FDT-1'!$AB19,"") | N11: =IF($U11<>"",'HPDB FDT-1'!$AC19,"") | O11: =IF('HPDB FDT-1'!$AD19="","",'HPDB FDT-1'!$AD19) | T11: =IF('HPDB FDT-1'!$AI19="","",'HPDB FDT-1'!$AI19) | U11: =IF('HPDB FDT-1'!$AJ19="","",'HPDB FDT-1'!$AJ19) | V11: =IF($U11<>"","Single Dwelling Unit","") | AB11: =IF($U11<>"","RFS","") | AC11: =IF($U11<>"",'HPDB FDT-1'!$Q$3,"") | AD11: =IF($U11<>"",'HPDB FDT-1'!$Q$4,"") | AE11: =IF($U11<>"",'HPDB FDT-1'!$C$6,"") | AF11: =IF($U11<>"",'HPDB FDT-1'!$AT19,"") | AG11: =IF($A11<>"",'CLUSTER FDT-1'!$H$2,"") | AH11: =IF('HPDB FDT-1'!$AV19="","",'HPDB FDT-1'!$AV19) | AI11: =IF('HPDB FDT-1'!$AW19="","",'HPDB FDT-1'!$AW19) | AK11: =IF($U11<>"",'HPDB FDT-1'!$AX19,"") | AL11: =IF($U11<>"",'HPDB FDT-1'!$AY19,"") | AM11: =IF($U11<>"",'HPDB FDT-1'!$AZ19,"") | AN11: =IF($U11<>"",'HPDB FDT-1'!$BA19,"") | AO11: =IF($U11<>"",'HPDB FDT-1'!$BB19,"") | AP11: =IF($U11<>"","RFS","") | AR11: =IF($U11<>"","31","") | AS11: =IF($U11<>"","FALSE","") | AT11: =IF($U11<>"","TRUE","")
A12: =IF($U12<>"",'HPDB FDT-1'!$Q20,"") | B12: =IF($U12<>"",'HPDB FDT-1'!$R20,"") | C12: =IF($U12<>"",'HPDB FDT-1'!$S20,"") | D12: =IF($U12<>"",'HPDB FDT-1'!$T20,"") | E12: =IF($U12<>"","FTTH","") | F12: =IF($U12<>"",'HPDB FDT-1'!$V20,"") | G12: =IF($U12<>"","General Retail","") | H12: =IF($U12<>"",'CLUSTER FDT-1'!$A$2,"") | J12: =IF($U12<>"",'CLUSTER FDT-1'!$A$2,"") | K12: =IF($U12<>"",'CLUSTER FDT-1'!$A$2,"") | L12: =IF($U12<>"",'HPDB FDT-1'!$AA20,"") | M12: =IF($U12<>"",'HPDB FDT-1'!$AB20,"") | N12: =IF($U12<>"",'HPDB FDT-1'!$AC20,"") | O12: =IF('HPDB FDT-1'!$AD20="","",'HPDB FDT-1'!$AD20) | T12: =IF('HPDB FDT-1'!$AI20="","",'HPDB FDT-1'!$AI20) | U12: =IF('HPDB FDT-1'!$AJ20="","",'HPDB FDT-1'!$AJ20) | V12: =IF($U12<>"","Single Dwelling Unit","") | AB12: =IF($U12<>"","RFS","") | AC12: =IF($U12<>"",'HPDB FDT-1'!$Q$3,"") | AD12: =IF($U12<>"",'HPDB FDT-1'!$Q$4,"") | AE12: =IF($U12<>"",'HPDB FDT-1'!$C$6,"") | AF12: =IF($U12<>"",'HPDB FDT-1'!$AT20,"") | AG12: =IF($A12<>"",'CLUSTER FDT-1'!$H$2,"") | AH12: =IF('HPDB FDT-1'!$AV20="","",'HPDB FDT-1'!$AV20) | AI12: =IF('HPDB FDT-1'!$AW20="","",'HPDB FDT-1'!$AW20) | AK12: =IF($U12<>"",'HPDB FDT-1'!$AX20,"") | AL12: =IF($U12<>"",'HPDB FDT-1'!$AY20,"") | AM12: =IF($U12<>"",'HPDB FDT-1'!$AZ20,"") | AN12: =IF($U12<>"",'HPDB FDT-1'!$BA20,"") | AO12: =IF($U12<>"",'HPDB FDT-1'!$BB20,"") | AP12: =IF($U12<>"","RFS","") | AR12: =IF($U12<>"","31","") | AS12: =IF($U12<>"","FALSE","") | AT12: =IF($U12<>"","TRUE","")
A13: =IF($U13<>"",'HPDB FDT-1'!$Q21,"") | B13: =IF($U13<>"",'HPDB FDT-1'!$R21,"") | C13: =IF($U13<>"",'HPDB FDT-1'!$S21,"") | D13: =IF($U13<>"",'HPDB FDT-1'!$T21,"") | E13: =IF($U13<>"","FTTH","") | F13: =IF($U13<>"",'HPDB FDT-1'!$V21,"") | G13: =IF($U13<>"","General Retail","") | H13: =IF($U13<>"",'CLUSTER FDT-1'!$A$2,"") | J13: =IF($U13<>"",'CLUSTER FDT-1'!$A$2,"") | K13: =IF($U13<>"",'CLUSTER FDT-1'!$A$2,"") | L13: =IF($U13<>"",'HPDB FDT-1'!$AA21,"") | M13: =IF($U13<>"",'HPDB FDT-1'!$AB21,"") | N13: =IF($U13<>"",'HPDB FDT-1'!$AC21,"") | O13: =IF('HPDB FDT-1'!$AD21="","",'HPDB FDT-1'!$AD21) | T13: =IF('HPDB FDT-1'!$AI21="","",'HPDB FDT-1'!$AI21) | U13: =IF('HPDB FDT-1'!$AJ21="","",'HPDB FDT-1'!$AJ21) | V13: =IF($U13<>"","Single Dwelling Unit","") | AB13: =IF($U13<>"","RFS","") | AC13: =IF($U13<>"",'HPDB FDT-1'!$Q$3,"") | AD13: =IF($U13<>"",'HPDB FDT-1'!$Q$4,"") | AE13: =IF($U13<>"",'HPDB FDT-1'!$C$6,"") | AF13: =IF($U13<>"",'HPDB FDT-1'!$AT21,"") | AG13: =IF($A13<>"",'CLUSTER FDT-1'!$H$2,"") | AH13: =IF('HPDB FDT-1'!$AV21="","",'HPDB FDT-1'!$AV21) | AI13: =IF('HPDB FDT-1'!$AW21="","",'HPDB FDT-1'!$AW21) | AK13: =IF($U13<>"",'HPDB FDT-1'!$AX21,"") | AL13: =IF($U13<>"",'HPDB FDT-1'!$AY21,"") | AM13: =IF($U13<>"",'HPDB FDT-1'!$AZ21,"") | AN13: =IF($U13<>"",'HPDB FDT-1'!$BA21,"") | AO13: =IF($U13<>"",'HPDB FDT-1'!$BB21,"") | AP13: =IF($U13<>"","RFS","") | AR13: =IF($U13<>"","31","") | AS13: =IF($U13<>"","FALSE","") | AT13: =IF($U13<>"","TRUE","")
A14: =IF($U14<>"",'HPDB FDT-1'!$Q22,"") | B14: =IF($U14<>"",'HPDB FDT-1'!$R22,"") | C14: =IF($U14<>"",'HPDB FDT-1'!$S22,"") | D14: =IF($U14<>"",'HPDB FDT-1'!$T22,"") | E14: =IF($U14<>"","FTTH","") | F14: =IF($U14<>"",'HPDB FDT-1'!$V22,"") | G14: =IF($U14<>"","General Retail","") | H14: =IF($U14<>"",'CLUSTER FDT-1'!$A$2,"") | J14: =IF($U14<>"",'CLUSTER FDT-1'!$A$2,"") | K14: =IF($U14<>"",'CLUSTER FDT-1'!$A$2,"") | L14: =IF($U14<>"",'HPDB FDT-1'!$AA22,"") | M14: =IF($U14<>"",'HPDB FDT-1'!$AB22,"") | N14: =IF($U14<>"",'HPDB FDT-1'!$AC22,"") | O14: =IF('HPDB FDT-1'!$AD22="","",'HPDB FDT-1'!$AD22) | T14: =IF('HPDB FDT-1'!$AI22="","",'HPDB FDT-1'!$AI22) | U14: =IF('HPDB FDT-1'!$AJ22="","",'HPDB FDT-1'!$AJ22) | V14: =IF($U14<>"","Single Dwelling Unit","") | AB14: =IF($U14<>"","RFS","") | AC14: =IF($U14<>"",'HPDB FDT-1'!$Q$3,"") | AD14: =IF($U14<>"",'HPDB FDT-1'!$Q$4,"") | AE14: =IF($U14<>"",'HPDB FDT-1'!$C$6,"") | AF14: =IF($U14<>"",'HPDB FDT-1'!$AT22,"") | AG14: =IF($A14<>"",'CLUSTER FDT-1'!$H$2,"") | AH14: =IF('HPDB FDT-1'!$AV22="","",'HPDB FDT-1'!$AV22) | AI14: =IF('HPDB FDT-1'!$AW22="","",'HPDB FDT-1'!$AW22) | AK14: =IF($U14<>"",'HPDB FDT-1'!$AX22,"") | AL14: =IF($U14<>"",'HPDB FDT-1'!$AY22,"") | AM14: =IF($U14<>"",'HPDB FDT-1'!$AZ22,"") | AN14: =IF($U14<>"",'HPDB FDT-1'!$BA22,"") | AO14: =IF($U14<>"",'HPDB FDT-1'!$BB22,"") | AP14: =IF($U14<>"","RFS","") | AR14: =IF($U14<>"","31","") | AS14: =IF($U14<>"","FALSE","") | AT14: =IF($U14<>"","TRUE","")
... A2500: =IF($U2500<>"",'HPDB FDT-1'!$Q2508,"") | B2500: =IF($U2500<>"",'HPDB FDT-1'!$R2508,"") | C2500: =IF($U2500<>"",'HPDB FDT-1'!$S2508,"") | D2500: =IF($U2500<>"",'HPDB FDT-1'!$T2508,"") | E2500: =IF($U2500<>"","FTTH","") | F2500: =IF($U2500<>"",'HPDB FDT-1'!$V2508,"") | G2500: =IF($U2500<>"","General Retail","") | H2500: =IF($U2500<>"",'CLUSTER FDT-1'!$A$2,"") | J2500: =IF($U2500<>"",'CLUSTER FDT-1'!$A$2,"") | K2500: =IF($U2500<>"",'CLUSTER FDT-1'!$A$2,"") | L2500: =IF($U2500<>"",'HPDB FDT-1'!$AA2508,"") | M2500: =IF($U2500<>"",'HPDB FDT-1'!$AB2508,"") | N2500: =IF($U2500<>"",'HPDB FDT-1'!$AC2508,"") | O2500: =IF('HPDB FDT-1'!$AD2508="","",'HPDB FDT-1'!$AD2508) | T2500: =IF('HPDB FDT-1'!$AI2508="","",'HPDB FDT-1'!$AI2508) | U2500: =IF('HPDB FDT-1'!$AJ2508="","",'HPDB FDT-1'!$AJ2508) | V2500: =IF($U2500<>"","Single Dwelling Unit","") | AB2500: =IF($U2500<>"","RFS","") | AC2500: =IF($U2500<>"",'HPDB FDT-1'!$Q$3,"") | AD2500: =IF($U2500<>"",'HPDB FDT-1'!$Q$4,"") | AE2500: =IF($U2500<>"",'HPDB FDT-1'!$C$6,"") | AF2500: =IF($U2500<>"",'HPDB FDT-1'!$AT2508,"") | AG2500: =IF($A2500<>"",'CLUSTER FDT-1'!$H$2,"") | AH2500: =IF('HPDB FDT-1'!$AV2508="","",'HPDB FDT-1'!$AV2508) | AI2500: =IF('HPDB FDT-1'!$AW2508="","",'HPDB FDT-1'!$AW2508) | AK2500: =IF($U2500<>"",'HPDB FDT-1'!$AX2508,"") | AL2500: =IF($U2500<>"",'HPDB FDT-1'!$AY2508,"") | AM2500: =IF($U2500<>"",'HPDB FDT-1'!$AZ2508,"") | AN2500: =IF($U2500<>"",'HPDB FDT-1'!$BA2508,"") | AO2500: =IF($U2500<>"",'HPDB FDT-1'!$BB2508,"") | AP2500: =IF($U2500<>"","RFS","") | AR2500: =IF($U2500<>"","31","") | AS2500: =IF($U2500<>"","FALSE","") | AT2500: =IF($U2500<>"","TRUE","")

Sheet HPDB FDT-2
A1: FIBER CORE ASSIGNMENT
A3: Region | C3: GARUT | L3: FDT TYPE | N3: 48 Core | P3: OLT CODE | Q3: =VLOOKUP('HPDB FDT-2'!$C$4,OLT!$A$2:$C$14,2,FALSE)
A4: OLT / Feeder Line | C4: OLT LELES | L4: HP / Construction type | N4: =AJ8 | P4: OLT Hostname | Q4: =VLOOKUP('HPDB FDT-2'!$C$4,OLT!$A$2:$C$14,3,FALSE)
A5: Cluster Name | C5: SUKAGALIH RW 10 | L5: Distance From OLT | N5: : XXX | P5: RFS DATE | Q5: 46115
A6: FDT ID | C6: CMPK.100 | L6: COORDINATE FDT | M6: LATITUDE | N6: -7.3314997 | P6: SYMBOL WARNA | Q6: KETERANGAN
A7: Cluster Code Astri | C7: GRT2345 | M7: LONGTITUDE | N7: 107.80799 | P7: CYAN | Q7: WARNA CELL YANG BOLEH DIISI
AJ8: =COUNTA(AJ10:AJ337)
A9: FDT Tray (Front) | B9: FDT Port | C9: Line | D9: Capacity | E9: Tube Colour | F9: Core Number | G9: FAT ID | H9: FAT Port | I9: Pole ID | J9: Pole Latitude | K9: Pole Longitude | L9: FAT Address | M9: Province | N9: regency_city | O9: district | P9: subdistrict | Q9: postalcode | R9: Roll_Out_ID | S9: acquisition_class | T9: acquisition_tier | U9: competition | V9: project_id | W9: Area | X9: Complex_name | Y9: Clustername | Z9: Commercial_name | AA9: Rw | AB9: Rt | AC9: address_prefix | AD9: street | AE9: address_suffix | AF9: sub_address_prefix | AG9: sub_address | AH9: sub_address_suffix | AI9: block | AJ9: homenumber | AK9: dwelling_type | AL9: building_type | AM9: building_property_name | AN9: building_property_location | AO9: floor | AP9: unit | AQ9: homepass_source | AR9: oltcode | AS9: fdtcode | AT9: fatcode | AU9: RFSDate | AV9: Latitude_homepass | AW9: Longitude_homepass | AX9: residential_service_ready | AY9: sme_service_ready | AZ9: enterprise_service_ready | BA9: installation | BB9: availability | BC9: network_presence | BD9: wallplate_installation
A10: G1 | B10: 1 | C10: LINE A | D10: 48C/4T | E10: 1 | F10: 1 | G10: A01 | H10: 1 | I10: =VLOOKUP(G10,'FAT HPDB FDT-2'!$A$1:$D$41,4,FALSE) | J10: =VLOOKUP(G10,'FAT HPDB FDT-2'!$A$1:$D$41,2,FALSE) | K10: =VLOOKUP(G10,'FAT HPDB FDT-2'!$A$1:$D$41,3,FALSE) | M10: JAWA BARAT | N10: GARUT | O10: KARANGPAWITAN | P10: KARANGSARI | Q10: {=_xlfn.XLOOKUP(1, (Data!A:A=N10)*(Data!B:B=O10)*(Data!C:C=P10), Data!D:D)} | R10: ="GRT."&TEXT(Q5,"mmyy") | S10: C | T10: 3 | U10: FTTH | V10: 2 | W10: GARUT | Y10: =UPPER($C$5) | Z10: =UPPER($C$5) | AA10: 3 | AB10: 2 | AC10: Jalan | AD10: CIMANUK | AI10: C | AJ10: NN-11 | AK10: Single Dwelling Unit | AM10: Rumah Sakit Betesda | AN10: -7.374590, 107.749493 | AQ10: RFS | AR10: =$Q$3 | AS10: =$C$6 | AT10: =$G10 | AU10: =Q5 | AV10: -7.37459 | AW10: 107.74949 | AX10: TRUE | AY10: FALSE | AZ10: FALSE | BA10: AE | BB10: TRUE | BC10: 31 | BD10: FALSE
C11: LINE A | D11: 48C/4T | E11: 1 | F11: 2 | G11: A01 | H11: =H10+1 | I11: =$I10 | J11: =$J10 | K11: =$K10 | L11: =$L10 | M11: =M$10 | N11: =N$10 | O11: =O$10 | P11: =P$10 | Q11: =Q$10 | R11: =R$10 | S11: =S$10 | T11: =T$10 | ... W11: =W$10 | Y11: =Y$10 | Z11: =Z$10 | AA11: 3 | AB11: 1 | AC11: =AC$10 | AJ11: NN-33 | AK11: =AK$10 | AQ11: =AQ$10 | AR11: =AR$10 | AS11: =AS$10 | AT11: =$AT10 | AU11: =AU$10 | AX11: =AX$10 | AY11: =AY$10 | AZ11: =AZ$10 | BA11: =BA$10 | BB11: =BB$10 | BC11: =BC$10 | BD11: =BD$10
H12: =H11+1 | I12: =$I10 | J12: =$J10 | K12: =$K10 | L12: =$L10 | M12: =M$10 | N12: =N$10 | O12: =O$10 | P12: =P$10 | Q12: =Q$10 | R12: =R$10 | S12: =S$10 | T12: =T$10 | ... W12: =W$10 | Y12: =Y$10 | Z12: =Z$10 | AC12: =AC$10 | AK12: =AK$10 | AQ12: =AQ$10 | AR12: =AR$10 | AS12: =AS$10 | AT12: =$AT10 | AU12: =AU$10 | AX12: =AX$10 | AY12: =AY$10 | AZ12: =AZ$10 | BA12: =BA$10 | BB12: =BB$10 | BC12: =BC$10 | BD12: =BD$10
H13: =H12+1 | I13: =$I10 | J13: =$J10 | K13: =$K10 | L13: =$L10 | M13: =M$10 | N13: =N$10 | O13: =O$10 | P13: =P$10 | Q13: =Q$10 | R13: =R$10 | S13: =S$10 | T13: =T$10 | ... W13: =W$10 | Y13: =Y$10 | Z13: =Z$10 | AC13: =AC$10 | AK13: =AK$10 | AQ13: =AQ$10 | AR13: =AR$10 | AS13: =AS$10 | AT13: =$AT10 | AU13: =AU$10 | AX13: =AX$10 | AY13: =AY$10 | AZ13: =AZ$10 | BA13: =BA$10 | BB13: =BB$10 | BC13: =BC$10 | BD13: =BD$10
H14: =H13+1 | I14: =$I10 | J14: =$J10 | K14: =$K10 | L14: =$L10 | M14: =M$10 | N14: =N$10 | O14: =O$10 | P14: =P$10 | Q14: =Q$10 | R14: =R$10 | S14: =S$10 | T14: =T$10 | ... W14: =W$10 | Y14: =Y$10 | Z14: =Z$10 | AC14: =AC$10 | AK14: =AK$10 | AQ14: =AQ$10 | AR14: =AR$10 | AS14: =AS$10 | AT14: =$AT10 | AU14: =AU$10 | AX14: =AX$10 | AY14: =AY$10 | AZ14: =AZ$10 | BA14: =BA$10 | BB14: =BB$10 | BC14: =BC$10 | BD14: =BD$10
H15: =H14+1 | I15: =$I10 | J15: =$J10 | K15: =$K10 | L15: =$L10 | M15: =M$10 | N15: =N$10 | O15: =O$10 | P15: =P$10 | Q15: =Q$10 | R15: =R$10 | S15: =S$10 | T15: =T$10 | ... W15: =W$10 | Y15: =Y$10 | Z15: =Z$10 | AC15: =AC$10 | AK15: =AK$10 | AQ15: =AQ$10 | AR15: =AR$10 | AS15: =AS$10 | AT15: =$AT10 | AU15: =AU$10 | AX15: =AX$10 | AY15: =AY$10 | AZ15: =AZ$10 | BA15: =BA$10 | BB15: =BB$10 | BC15: =BC$10 | BD15: =BD$10
H16: =H15+1 | I16: =$I10 | J16: =$J10 | K16: =$K10 | L16: =$L10 | M16: =M$10 | N16: =N$10 | O16: =O$10 | P16: =P$10 | Q16: =Q$10 | R16: =R$10 | S16: =S$10 | T16: =T$10 | ... W16: =W$10 | Y16: =Y$10 | Z16: =Z$10 | AC16: =AC$10 | AK16: =AK$10 | AQ16: =AQ$10 | AR16: =AR$10 | AS16: =AS$10 | AT16: =$AT10 | AU16: =AU$10 | AX16: =AX$10 | AY16: =AY$10 | AZ16: =AZ$10 | BA16: =BA$10 | BB16: =BB$10 | BC16: =BC$10 | BD16: =BD$10
H17: =H16+1 | I17: =$I10 | J17: =$J10 | K17: =$K10 | L17: =$L10 | M17: =M$10 | N17: =N$10 | O17: =O$10 | P17: =P$10 | Q17: =Q$10 | R17: =R$10 | S17: =S$10 | T17: =T$10 | ... W17: =W$10 | Y17: =Y$10 | Z17: =Z$10 | AC17: =AC$10 | AK17: =AK$10 | AQ17: =AQ$10 | AR17: =AR$10 | AS17: =AS$10 | AT17: =$AT10 | AU17: =AU$10 | AX17: =AX$10 | AY17: =AY$10 | AZ17: =AZ$10 | BA17: =BA$10 | BB17: =BB$10 | BC17: =BC$10 | BD17: =BD$10
H18: =H17+1 | I18: =$I10 | J18: =$J10 | K18: =$K10 | L18: =$L10 | M18: =M$10 | N18: =N$10 | O18: =O$10 | P18: =P$10 | Q18: =Q$10 | R18: =R$10 | S18: =S$10 | T18: =T$10 | ... W18: =W$10 | Y18: =Y$10 | Z18: =Z$10 | AC18: =AC$10 | AK18: =AK$10 | AQ18: =AQ$10 | AR18: =AR$10 | AS18: =AS$10 | AT18: =$AT10 | AU18: =AU$10 | AX18: =AX$10 | AY18: =AY$10 | AZ18: =AZ$10 | BA18: =BA$10 | BB18: =BB$10 | BC18: =BC$10 | BD18: =BD$10
H19: =H18+1 | I19: =$I10 | J19: =$J10 | K19: =$K10 | L19: =$L10 | M19: =M$10 | N19: =N$10 | O19: =O$10 | P19: =P$10 | Q19: =Q$10 | R19: =R$10 | S19: =S$10 | T19: =T$10 | ... W19: =W$10 | Y19: =Y$10 | Z19: =Z$10 | AC19: =AC$10 | AK19: =AK$10 | AQ19: =AQ$10 | AR19: =AR$10 | AS19: =AS$10 | AT19: =$AT10 | AU19: =AU$10 | AX19: =AX$10 | AY19: =AY$10 | AZ19: =AZ$10 | BA19: =BA$10 | BB19: =BB$10 | BC19: =BC$10 | BD19: =BD$10
H20: =H19+1 | I20: =$I10 | J20: =$J10 | K20: =$K10 | L20: =$L10 | M20: =M$10 | N20: =N$10 | O20: =O$10 | P20: =P$10 | Q20: =Q$10 | R20: =R$10 | S20: =S$10 | T20: =T$10 | ... W20: =W$10 | Y20: =Y$10 | Z20: =Z$10 | AC20: =AC$10 | AK20: =AK$10 | AQ20: =AQ$10 | AR20: =AR$10 | AS20: =AS$10 | AT20: =$AT10 | AU20: =AU$10 | AX20: =AX$10 | AY20: =AY$10 | AZ20: =AZ$10 | BA20: =BA$10 | BB20: =BB$10 | BC20: =BC$10 | BD20: =BD$10
H21: =H20+1 | I21: =$I10 | J21: =$J10 | K21: =$K10 | L21: =$L10 | M21: =M$10 | N21: =N$10 | O21: =O$10 | P21: =P$10 | Q21: =Q$10 | R21: =R$10 | S21: =S$10 | T21: =T$10 | ... W21: =W$10 | Y21: =Y$10 | Z21: =Z$10 | AC21: =AC$10 | AK21: =AK$10 | AQ21: =AQ$10 | AR21: =AR$10 | AS21: =AS$10 | AT21: =$AT10 | AU21: =AU$10 | AX21: =AX$10 | AY21: =AY$10 | AZ21: =AZ$10 | BA21: =BA$10 | BB21: =BB$10 | BC21: =BC$10 | BD21: =BD$10
H22: =H21+1 | I22: =$I10 | J22: =$J10 | K22: =$K10 | L22: =$L10 | M22: =M$10 | N22: =N$10 | O22: =O$10 | P22: =P$10 | Q22: =Q$10 | R22: =R$10 | S22: =S$10 | T22: =T$10 | ... W22: =W$10 | Y22: =Y$10 | Z22: =Z$10 | AC22: =AC$10 | AK22: =AK$10 | AQ22: =AQ$10 | AR22: =AR$10 | AS22: =AS$10 | AT22: =$AT10 | AU22: =AU$10 | AX22: =AX$10 | AY22: =AY$10 | AZ22: =AZ$10 | BA22: =BA$10 | BB22: =BB$10 | BC22: =BC$10 | BD22: =BD$10
H23: =H22+1 | I23: =$I10 | J23: =$J10 | K23: =$K10 | L23: =$L10 | M23: =M$10 | N23: =N$10 | O23: =O$10 | P23: =P$10 | Q23: =Q$10 | R23: =R$10 | S23: =S$10 | T23: =T$10 | ... W23: =W$10 | Y23: =Y$10 | Z23: =Z$10 | AC23: =AC$10 | AK23: =AK$10 | AQ23: =AQ$10 | AR23: =AR$10 | AS23: =AS$10 | AT23: =$AT10 | AU23: =AU$10 | AX23: =AX$10 | AY23: =AY$10 | AZ23: =AZ$10 | BA23: =BA$10 | BB23: =BB$10 | BC23: =BC$10 | BD23: =BD$10
H24: =H23+1 | I24: =$I10 | J24: =$J10 | K24: =$K10 | L24: =$L10 | M24: =M$10 | N24: =N$10 | O24: =O$10 | P24: =P$10 | Q24: =Q$10 | R24: =R$10 | S24: =S$10 | T24: =T$10 | ... W24: =W$10 | Y24: =Y$10 | Z24: =Z$10 | AC24: =AC$10 | AK24: =AK$10 | AQ24: =AQ$10 | AR24: =AR$10 | AS24: =AS$10 | AT24: =$AT10 | AU24: =AU$10 | AX24: =AX$10 | AY24: =AY$10 | AZ24: =AZ$10 | BA24: =BA$10 | BB24: =BB$10 | BC24: =BC$10 | BD24: =BD$10
H25: =H24+1 | I25: =$I10 | J25: =$J10 | K25: =$K10 | L25: =$L10 | M25: =M$10 | N25: =N$10 | O25: =O$10 | P25: =P$10 | Q25: =Q$10 | R25: =R$10 | S25: =S$10 | T25: =T$10 | ... W25: =W$10 | Y25: =Y$10 | Z25: =Z$10 | AC25: =AC$10 | AK25: =AK$10 | AQ25: =AQ$10 | AR25: =AR$10 | AS25: =AS$10 | AT25: =$AT10 | AU25: =AU$10 | AX25: =AX$10 | AY25: =AY$10 | AZ25: =AZ$10 | BA25: =BA$10 | BB25: =BB$10 | BC25: =BC$10 | BD25: =BD$10
A26: G1 | B26: 2 | C26: LINE A | D26: 48C/4T | E26: 1 | F26: 3 | G26: A02 | H26: 1 | I26: =VLOOKUP(G26,'FAT HPDB FDT-2'!$A$1:$D$41,4,FALSE) | J26: =VLOOKUP(G26,'FAT HPDB FDT-2'!$A$1:$D$41,2,FALSE) | K26: =VLOOKUP(G26,'FAT HPDB FDT-2'!$A$1:$D$41,3,FALSE) | M26: =M$10 | N26: =N$10 | O26: =O$10 | P26: =P$10 | Q26: =Q$10 | R26: =R$10 | S26: =S$10 | T26: =T$10 | ... W26: =W$10 | Y26: =Y$10 | Z26: =Z$10 | AC26: =AC$10 | AK26: =AK$10 | AQ26: =AQ$10 | AR26: =AR$10 | AS26: =AS$10 | AT26: =$G26 | AU26: =AU$10 | AX26: =AX$10 | AY26: =AY$10 | AZ26: =AZ$10 | BA26: =BA$10 | BB26: =BB$10 | BC26: =BC$10 | BD26: =BD$10
C27: LINE A | D27: 48C/4T | E27: 1 | F27: 4 | G27: A02 | H27: =H26+1 | I27: =$I26 | J27: =$J26 | K27: =$K26 | L27: =$L26 | M27: =M$10 | N27: =N$10 | O27: =O$10 | P27: =P$10 | Q27: =Q$10 | R27: =R$10 | S27: =S$10 | T27: =T$10 | ... W27: =W$10 | Y27: =Y$10 | Z27: =Z$10 | AC27: =AC$10 | AK27: =AK$10 | AQ27: =AQ$10 | AR27: =AR$10 | AS27: =AS$10 | AT27: =$AT26 | AU27: =AU$10 | AX27: =AX$10 | AY27: =AY$10 | AZ27: =AZ$10 | BA27: =BA$10 | BB27: =BB$10 | BC27: =BC$10 | BD27: =BD$10
H28: =H27+1 | I28: =$I26 | J28: =$J26 | K28: =$K26 | L28: =$L26 | M28: =M$10 | N28: =N$10 | O28: =O$10 | P28: =P$10 | Q28: =Q$10 | R28: =R$10 | S28: =S$10 | T28: =T$10 | ... W28: =W$10 | Y28: =Y$10 | Z28: =Z$10 | AC28: =AC$10 | AK28: =AK$10 | AQ28: =AQ$10 | AR28: =AR$10 | AS28: =AS$10 | AT28: =$AT26 | AU28: =AU$10 | AX28: =AX$10 | AY28: =AY$10 | AZ28: =AZ$10 | BA28: =BA$10 | BB28: =BB$10 | BC28: =BC$10 | BD28: =BD$10
H29: =H28+1 | I29: =$I26 | J29: =$J26 | K29: =$K26 | L29: =$L26 | M29: =M$10 | N29: =N$10 | O29: =O$10 | P29: =P$10 | Q29: =Q$10 | R29: =R$10 | S29: =S$10 | T29: =T$10 | ... W29: =W$10 | Y29: =Y$10 | Z29: =Z$10 | AC29: =AC$10 | AK29: =AK$10 | AQ29: =AQ$10 | AR29: =AR$10 | AS29: =AS$10 | AT29: =$AT26 | AU29: =AU$10 | AX29: =AX$10 | AY29: =AY$10 | AZ29: =AZ$10 | BA29: =BA$10 | BB29: =BB$10 | BC29: =BC$10 | BD29: =BD$10
H30: =H29+1 | I30: =$I26 | J30: =$J26 | K30: =$K26 | L30: =$L26 | M30: =M$10 | N30: =N$10 | O30: =O$10 | P30: =P$10 | Q30: =Q$10 | R30: =R$10 | S30: =S$10 | T30: =T$10 | ... W30: =W$10 | Y30: =Y$10 | Z30: =Z$10 | AC30: =AC$10 | AK30: =AK$10 | AQ30: =AQ$10 | AR30: =AR$10 | AS30: =AS$10 | AT30: =$AT26 | AU30: =AU$10 | AX30: =AX$10 | AY30: =AY$10 | AZ30: =AZ$10 | BA30: =BA$10 | BB30: =BB$10 | BC30: =BC$10 | BD30: =BD$10
H31: =H30+1 | I31: =$I26 | J31: =$J26 | K31: =$K26 | L31: =$L26 | M31: =M$10 | N31: =N$10 | O31: =O$10 | P31: =P$10 | Q31: =Q$10 | R31: =R$10 | S31: =S$10 | T31: =T$10 | ... W31: =W$10 | Y31: =Y$10 | Z31: =Z$10 | AC31: =AC$10 | AK31: =AK$10 | AQ31: =AQ$10 | AR31: =AR$10 | AS31: =AS$10 | AT31: =$AT26 | AU31: =AU$10 | AX31: =AX$10 | AY31: =AY$10 | AZ31: =AZ$10 | BA31: =BA$10 | BB31: =BB$10 | BC31: =BC$10 | BD31: =BD$10
H32: =H31+1 | I32: =$I26 | J32: =$J26 | K32: =$K26 | L32: =$L26 | M32: =M$10 | N32: =N$10 | O32: =O$10 | P32: =P$10 | Q32: =Q$10 | R32: =R$10 | S32: =S$10 | T32: =T$10 | ... W32: =W$10 | Y32: =Y$10 | Z32: =Z$10 | AC32: =AC$10 | AK32: =AK$10 | AQ32: =AQ$10 | AR32: =AR$10 | AS32: =AS$10 | AT32: =$AT26 | AU32: =AU$10 | AX32: =AX$10 | AY32: =AY$10 | AZ32: =AZ$10 | BA32: =BA$10 | BB32: =BB$10 | BC32: =BC$10 | BD32: =BD$10
H33: =H32+1 | I33: =$I26 | J33: =$J26 | K33: =$K26 | L33: =$L26 | M33: =M$10 | N33: =N$10 | O33: =O$10 | P33: =P$10 | Q33: =Q$10 | R33: =R$10 | S33: =S$10 | T33: =T$10 | ... W33: =W$10 | Y33: =Y$10 | Z33: =Z$10 | AC33: =AC$10 | AK33: =AK$10 | AQ33: =AQ$10 | AR33: =AR$10 | AS33: =AS$10 | AT33: =$AT26 | AU33: =AU$10 | AX33: =AX$10 | AY33: =AY$10 | AZ33: =AZ$10 | BA33: =BA$10 | BB33: =BB$10 | BC33: =BC$10 | BD33: =BD$10
H34: =H33+1 | I34: =$I26 | J34: =$J26 | K34: =$K26 | L34: =$L26 | M34: =M$10 | N34: =N$10 | O34: =O$10 | P34: =P$10 | Q34: =Q$10 | R34: =R$10 | S34: =S$10 | T34: =T$10 | ... W34: =W$10 | Y34: =Y$10 | Z34: =Z$10 | AC34: =AC$10 | AK34: =AK$10 | AQ34: =AQ$10 | AR34: =AR$10 | AS34: =AS$10 | AT34: =$AT26 | AU34: =AU$10 | AX34: =AX$10 | AY34: =AY$10 | AZ34: =AZ$10 | BA34: =BA$10 | BB34: =BB$10 | BC34: =BC$10 | BD34: =BD$10
H35: =H34+1 | I35: =$I26 | J35: =$J26 | K35: =$K26 | L35: =$L26 | M35: =M$10 | N35: =N$10 | O35: =O$10 | P35: =P$10 | Q35: =Q$10 | R35: =R$10 | S35: =S$10 | T35: =T$10 | ... W35: =W$10 | Y35: =Y$10 | Z35: =Z$10 | AC35: =AC$10 | AK35: =AK$10 | AQ35: =AQ$10 | AR35: =AR$10 | AS35: =AS$10 | AT35: =$AT26 | AU35: =AU$10 | AX35: =AX$10 | AY35: =AY$10 | AZ35: =AZ$10 | BA35: =BA$10 | BB35: =BB$10 | BC35: =BC$10 | BD35: =BD$10
H36: =H35+1 | I36: =$I26 | J36: =$J26 | K36: =$K26 | L36: =$L26 | M36: =M$10 | N36: =N$10 | O36: =O$10 | P36: =P$10 | Q36: =Q$10 | R36: =R$10 | S36: =S$10 | T36: =T$10 | ... W36: =W$10 | Y36: =Y$10 | Z36: =Z$10 | AC36: =AC$10 | AK36: =AK$10 | AQ36: =AQ$10 | AR36: =AR$10 | AS36: =AS$10 | AT36: =$AT26 | AU36: =AU$10 | AX36: =AX$10 | AY36: =AY$10 | AZ36: =AZ$10 | BA36: =BA$10 | BB36: =BB$10 | BC36: =BC$10 | BD36: =BD$10
H37: =H36+1 | I37: =$I26 | J37: =$J26 | K37: =$K26 | L37: =$L26 | M37: =M$10 | N37: =N$10 | O37: =O$10 | P37: =P$10 | Q37: =Q$10 | R37: =R$10 | S37: =S$10 | T37: =T$10 | ... W37: =W$10 | Y37: =Y$10 | Z37: =Z$10 | AC37: =AC$10 | AK37: =AK$10 | AQ37: =AQ$10 | AR37: =AR$10 | AS37: =AS$10 | AT37: =$AT26 | AU37: =AU$10 | AX37: =AX$10 | AY37: =AY$10 | AZ37: =AZ$10 | BA37: =BA$10 | BB37: =BB$10 | BC37: =BC$10 | BD37: =BD$10
H38: =H37+1 | I38: =$I26 | J38: =$J26 | K38: =$K26 | L38: =$L26 | M38: =M$10 | N38: =N$10 | O38: =O$10 | P38: =P$10 | Q38: =Q$10 | R38: =R$10 | S38: =S$10 | T38: =T$10 | ... W38: =W$10 | Y38: =Y$10 | Z38: =Z$10 | AC38: =AC$10 | AK38: =AK$10 | AQ38: =AQ$10 | AR38: =AR$10 | AS38: =AS$10 | AT38: =$AT26 | AU38: =AU$10 | AX38: =AX$10 | AY38: =AY$10 | AZ38: =AZ$10 | BA38: =BA$10 | BB38: =BB$10 | BC38: =BC$10 | BD38: =BD$10
H39: =H38+1 | I39: =$I26 | J39: =$J26 | K39: =$K26 | L39: =$L26 | M39: =M$10 | N39: =N$10 | O39: =O$10 | P39: =P$10 | Q39: =Q$10 | R39: =R$10 | S39: =S$10 | T39: =T$10 | ... W39: =W$10 | Y39: =Y$10 | Z39: =Z$10 | AC39: =AC$10 | AK39: =AK$10 | AQ39: =AQ$10 | AR39: =AR$10 | AS39: =AS$10 | AT39: =$AT26 | AU39: =AU$10 | AX39: =AX$10 | AY39: =AY$10 | AZ39: =AZ$10 | BA39: =BA$10 | BB39: =BB$10 | BC39: =BC$10 | BD39: =BD$10
H40: =H39+1 | I40: =$I26 | J40: =$J26 | K40: =$K26 | L40: =$L26 | M40: =M$10 | N40: =N$10 | O40: =O$10 | P40: =P$10 | Q40: =Q$10 | R40: =R$10 | S40: =S$10 | T40: =T$10 | ... W40: =W$10 | Y40: =Y$10 | Z40: =Z$10 | AC40: =AC$10 | AK40: =AK$10 | AQ40: =AQ$10 | AR40: =AR$10 | AS40: =AS$10 | AT40: =$AT26 | AU40: =AU$10 | AX40: =AX$10 | AY40: =AY$10 | AZ40: =AZ$10 | BA40: =BA$10 | BB40: =BB$10 | BC40: =BC$10 | BD40: =BD$10
H41: =H40+1 | I41: =$I26 | J41: =$J26 | K41: =$K26 | L41: =$L26 | M41: =M$10 | N41: =N$10 | O41: =O$10 | P41: =P$10 | Q41: =Q$10 | R41: =R$10 | S41: =S$10 | T41: =T$10 | ... W41: =W$10 | Y41: =Y$10 | Z41: =Z$10 | AC41: =AC$10 | AK41: =AK$10 | AQ41: =AQ$10 | AR41: =AR$10 | AS41: =AS$10 | AT41: =$AT26 | AU41: =AU$10 | AX41: =AX$10 | AY41: =AY$10 | AZ41: =AZ$10 | BA41: =BA$10 | BB41: =BB$10 | BC41: =BC$10 | BD41: =BD$10
...

Sheet FAT HPDB FDT-2
A1: LABEL | B1: LATITUDE | C1: LONGITUDE | D1: POLE ID | F1: Catatan : FAT yang tidak diperlukan harap di hapus saja datanya jangan di Delete Cell
A2: A01 | B2: 1 | C2: 2 | D2: MR.XXX.P001
A3: A02 | B3: 3 | C3: 4 | D3: MR.XXX.P002
A4: A03 | B4: 5 | C4: 6 | D4: MR.XXX.P003
A5: A04 | B5: 7 | C5: 8 | D5: MR.XXX.P004
A6: A05 | B6: 9 | C6: 10 | D6: MR.XXX.P005
A7: A06 | B7: 11 | C7: 12 | D7: MR.XXX.P006
A8: A07 | B8: 13 | C8: 14 | D8: MR.XXX.P007
A9: A08 | B9: 15 | C9: 16 | D9: MR.XXX.P008
A10: A09 | B10: 17 | C10: 18 | D10: MR.XXX.P009
A11: A10 | B11: 19 | C11: 20 | D11: MR.XXX.P010
A12: A11 | B12: 21 | C12: 22 | D12: MR.XXX.P011
A13: A12 | B13: 23 | C13: 24 | D13: MR.XXX.P012
... A41: B20 | B41: 79 | C41: 80 | D41: MR.XXX.P040

Sheet CLUSTER FDT-2
A1: cluster_name | B1: fdt_code | C1: commercial_name | D1: province | E1: competition | F1: city | G1: area_name | H1: rfs_date | I1: district | J1: acquisition_class | K1: acquisition_tier | L1: postal_code | M1: sub_district | N1: olt_code | O1: cluster_type | P1: complex | Q1: project_name | R1: project_id | S1: latitude_cluster | T1: longitude_cluster | U1: cluster_code_astri
A2: =IF('HPDB FDT-2'!$Y$10="","",'HPDB FDT-2'!$Y$10) | B2: =IF('HPDB FDT-2'!$C$6="","",'HPDB FDT-2'!$C$6) | C2: =IF($A$2="","",$A$2) | D2: =PROPER(IF('HPDB FDT-2'!$M$10="","",'HPDB FDT-2'!$M$10)) | E2: FTTH | F2: Kab. Garut | G2: Garut | H2: =IF('HPDB FDT-2'!$AU$10="","",'HPDB FDT-2'!$AU$10) | I2: =PROPER(IF('HPDB FDT-2'!$O$10="","",'HPDB FDT-2'!$O$10)) | J2: =IF('HPDB FDT-2'!$S$10="","",'HPDB FDT-2'!$S$10) | K2: =IF('HPDB FDT-2'!$T$10="","",'HPDB FDT-2'!$T$10) | L2: =IF('HPDB FDT-2'!$Q$10="","",'HPDB FDT-2'!$Q$10) | M2: =PROPER(IF('HPDB FDT-2'!$P$10="","",'HPDB FDT-2'!$P$10)) | N2: =IF('HPDB FDT-2'!$Q$3="","",'HPDB FDT-2'!$Q$3) | O2: Onnet | P2: =IF($A$2="","",$A$2) | Q2: General Retail | R2: =IF('HPDB FDT-2'!$V$10="","",'HPDB FDT-2'!$V$10) | S2: =IF('HPDB FDT-2'!$N$6="","",'HPDB FDT-2'!$N$6) | T2: =IF('HPDB FDT-2'!$N$7="","",'HPDB FDT-2'!$N$7) | U2: =IF('HPDB FDT-2'!$C$7="","",'HPDB FDT-2'!$C$7)

Sheet FAT FDT-2
A1: Area | B1: Clustername | C1: FAT Code | D1: FDT Code | E1: Port Count
A2: =IF($C2<>"","GARUT","") | B2: =IF($C2<>"",'CLUSTER FDT-2'!$A$2,"") | C2: =IF('FAT HPDB FDT-2'!$A2="","",'FAT HPDB FDT-2'!$A2) | D2: =IF($A2<>"",'HPDB FDT-2'!$C$6,"") | E2: =IF($A2<>"","16","")
A3: =IF($C3<>"","GARUT","") | B3: =IF($C3<>"",'CLUSTER FDT-2'!$A$2,"") | C3: =IF('FAT HPDB FDT-2'!$A3="","",'FAT HPDB FDT-2'!$A3) | D3: =IF($A3<>"",'HPDB FDT-2'!$C$6,"") | E3: =IF($A3<>"","16","")
A4: =IF($C4<>"","GARUT","") | B4: =IF($C4<>"",'CLUSTER FDT-2'!$A$2,"") | C4: =IF('FAT HPDB FDT-2'!$A4="","",'FAT HPDB FDT-2'!$A4) | D4: =IF($A4<>"",'HPDB FDT-2'!$C$6,"") | E4: =IF($A4<>"","16","")
A5: =IF($C5<>"","GARUT","") | B5: =IF($C5<>"",'CLUSTER FDT-2'!$A$2,"") | C5: =IF('FAT HPDB FDT-2'!$A5="","",'FAT HPDB FDT-2'!$A5) | D5: =IF($A5<>"",'HPDB FDT-2'!$C$6,"") | E5: =IF($A5<>"","16","")
A6: =IF($C6<>"","GARUT","") | B6: =IF($C6<>"",'CLUSTER FDT-2'!$A$2,"") | C6: =IF('FAT HPDB FDT-2'!$A6="","",'FAT HPDB FDT-2'!$A6) | D6: =IF($A6<>"",'HPDB FDT-2'!$C$6,"") | E6: =IF($A6<>"","16","")
A7: =IF($C7<>"","GARUT","") | B7: =IF($C7<>"",'CLUSTER FDT-2'!$A$2,"") | C7: =IF('FAT HPDB FDT-2'!$A7="","",'FAT HPDB FDT-2'!$A7) | D7: =IF($A7<>"",'HPDB FDT-2'!$C$6,"") | E7: =IF($A7<>"","16","")
A8: =IF($C8<>"","GARUT","") | B8: =IF($C8<>"",'CLUSTER FDT-2'!$A$2,"") | C8: =IF('FAT HPDB FDT-2'!$A8="","",'FAT HPDB FDT-2'!$A8) | D8: =IF($A8<>"",'HPDB FDT-2'!$C$6,"") | E8: =IF($A8<>"","16","")
A9: =IF($C9<>"","GARUT","") | B9: =IF($C9<>"",'CLUSTER FDT-2'!$A$2,"") | C9: =IF('FAT HPDB FDT-2'!$A9="","",'FAT HPDB FDT-2'!$A9) | D9: =IF($A9<>"",'HPDB FDT-2'!$C$6,"") | E9: =IF($A9<>"","16","")
A10: =IF($C10<>"","GARUT","") | B10: =IF($C10<>"",'CLUSTER FDT-2'!$A$2,"") | C10: =IF('FAT HPDB FDT-2'!$A10="","",'FAT HPDB FDT-2'!$A10) | D10: =IF($A10<>"",'HPDB FDT-2'!$C$6,"") | E10: =IF($A10<>"","16","")
A11: =IF($C11<>"","GARUT","") | B11: =IF($C11<>"",'CLUSTER FDT-2'!$A$2,"") | C11: =IF('FAT HPDB FDT-2'!$A11="","",'FAT HPDB FDT-2'!$A11) | D11: =IF($A11<>"",'HPDB FDT-2'!$C$6,"") | E11: =IF($A11<>"","16","")
A12: =IF($C12<>"","GARUT","") | B12: =IF($C12<>"",'CLUSTER FDT-2'!$A$2,"") | C12: =IF('FAT HPDB FDT-2'!$A12="","",'FAT HPDB FDT-2'!$A12) | D12: =IF($A12<>"",'HPDB FDT-2'!$C$6,"") | E12: =IF($A12<>"","16","")
A13: =IF($C13<>"","GARUT","") | B13: =IF($C13<>"",'CLUSTER FDT-2'!$A$2,"") | C13: =IF('FAT HPDB FDT-2'!$A13="","",'FAT HPDB FDT-2'!$A13) | D13: =IF($A13<>"",'HPDB FDT-2'!$C$6,"") | E13: =IF($A13<>"","16","")
... A100: =IF($C100<>"","GARUT","") | B100: =IF($C100<>"",'CLUSTER FDT-2'!$A$2,"") | C100: =IF('FAT HPDB FDT-2'!$A100="","",'FAT HPDB FDT-2'!$A100) | D100: =IF($A100<>"",'HPDB FDT-2'!$C$6,"") | E100: =IF($A100<>"","16","")

Sheet HOMEPASS FDT-2
A1: postalcode | B1: Roll_Out_ID | C1: acquisition_class | D1: acquisition_tier | E1: competition | F1: project_id | G1: projectName | H1: Complex_name | I1: ClusterId | J1: Clustername | K1: Commercial_name | L1: Rw | M1: Rt | N1: address_prefix | O1: street | P1: address_suffix | Q1: sub_address_prefix | R1: sub_address | S1: sub_address_suffix | T1: block | U1: homenumber | V1: dwelling_type | W1: building_type | X1: building_property_name | Y1: building_property_location | Z1: floor | AA1: unit | AB1: homepass_source | AC1: oltcode | AD1: olthostname | AE1: fdtcode | AF1: fatcode | AG1: RFSDate | AH1: Latitude_homepass | AI1: Longitude_homepass | AJ1: vendor_homepass_id | AK1: residential_service_ready | AL1: sme_service_ready | AM1: enterprise_service_ready | AN1: installation | AO1: availability | AP1: classification | AQ1: business_case | AR1: network_presence | AS1: wallplate_installation | AT1: publish
A2: =IF($U2<>"",'HPDB FDT-2'!$Q10,"") | B2: =IF($U2<>"",'HPDB FDT-2'!$R10,"") | C2: =IF($U2<>"",'HPDB FDT-2'!$S10,"") | D2: =IF($U2<>"",'HPDB FDT-2'!$T10,"") | E2: =IF($U2<>"","FTTH","") | F2: =IF($U2<>"",'HPDB FDT-2'!$V10,"") | G2: =IF($U2<>"","General Retail","") | H2: =IF($U2<>"",'CLUSTER FDT-2'!$A$2,"") | J2: =IF($U2<>"",'CLUSTER FDT-2'!$A$2,"") | K2: =IF($U2<>"",'CLUSTER FDT-2'!$A$2,"") | L2: =IF($U2<>"",'HPDB FDT-2'!$AA10,"") | M2: =IF($U2<>"",'HPDB FDT-2'!$AB10,"") | N2: =IF($U2<>"",'HPDB FDT-2'!$AC10,"") | O2: =IF('HPDB FDT-2'!$AD10="","",'HPDB FDT-2'!$AD10) | T2: =IF('HPDB FDT-2'!$AI10="","",'HPDB FDT-2'!$AI10) | U2: =IF('HPDB FDT-2'!$AJ10="","",'HPDB FDT-2'!$AJ10) | V2: =IF($U2<>"","Single Dwelling Unit","") | W2: j | AB2: =IF($U2<>"","RFS","") | AC2: =IF($U2<>"",'HPDB FDT-2'!$Q$3,"") | AD2: =IF($U2<>"",'HPDB FDT-2'!$Q$4,"") | AE2: =IF($U2<>"",'HPDB FDT-2'!$C$6,"") | AF2: =IF($U2<>"",'HPDB FDT-2'!$AT10,"") | AG2: =IF($A2<>"",'CLUSTER FDT-2'!$H$2,"") | AH2: =IF('HPDB FDT-2'!$AV10="","",'HPDB FDT-2'!$AV10) | AI2: =IF('HPDB FDT-2'!$AW10="","",'HPDB FDT-2'!$AW10) | AK2: =IF($U2<>"",'HPDB FDT-2'!$AX10,"") | AL2: =IF($U2<>"",'HPDB FDT-2'!$AY10,"") | AM2: =IF($U2<>"",'HPDB FDT-2'!$AZ10,"") | AN2: =IF($U2<>"",'HPDB FDT-2'!$BA10,"") | AO2: =IF($U2<>"",'HPDB FDT-2'!$BB10,"") | AP2: =IF($U2<>"","RFS","") | AR2: =IF($U2<>"","31","") | AS2: =IF($U2<>"","FALSE","") | AT2: =IF($U2<>"","TRUE","")
A3: =IF($U3<>"",'HPDB FDT-2'!$Q11,"") | B3: =IF($U3<>"",'HPDB FDT-2'!$R11,"") | C3: =IF($U3<>"",'HPDB FDT-2'!$S11,"") | D3: =IF($U3<>"",'HPDB FDT-2'!$T11,"") | E3: =IF($U3<>"","FTTH","") | F3: =IF($U3<>"",'HPDB FDT-2'!$V11,"") | G3: =IF($U3<>"","General Retail","") | H3: =IF($U3<>"",'CLUSTER FDT-2'!$A$2,"") | J3: =IF($U3<>"",'CLUSTER FDT-2'!$A$2,"") | K3: =IF($U3<>"",'CLUSTER FDT-2'!$A$2,"") | L3: =IF($U3<>"",'HPDB FDT-2'!$AA11,"") | M3: =IF($U3<>"",'HPDB FDT-2'!$AB11,"") | N3: =IF($U3<>"",'HPDB FDT-2'!$AC11,"") | O3: =IF('HPDB FDT-2'!$AD11="","",'HPDB FDT-2'!$AD11) | T3: =IF('HPDB FDT-2'!$AI11="","",'HPDB FDT-2'!$AI11) | U3: =IF('HPDB FDT-2'!$AJ11="","",'HPDB FDT-2'!$AJ11) | V3: =IF($U3<>"","Single Dwelling Unit","") | AB3: =IF($U3<>"","RFS","") | AC3: =IF($U3<>"",'HPDB FDT-2'!$Q$3,"") | AD3: =IF($U3<>"",'HPDB FDT-2'!$Q$4,"") | AE3: =IF($U3<>"",'HPDB FDT-2'!$C$6,"") | AF3: =IF($U3<>"",'HPDB FDT-2'!$AT11,"") | AG3: =IF($A3<>"",'CLUSTER FDT-2'!$H$2,"") | AH3: =IF('HPDB FDT-2'!$AV11="","",'HPDB FDT-2'!$AV11) | AI3: =IF('HPDB FDT-2'!$AW11="","",'HPDB FDT-2'!$AW11) | AK3: =IF($U3<>"",'HPDB FDT-2'!$AX11,"") | AL3: =IF($U3<>"",'HPDB FDT-2'!$AY11,"") | AM3: =IF($U3<>"",'HPDB FDT-2'!$AZ11,"") | AN3: =IF($U3<>"",'HPDB FDT-2'!$BA11,"") | AO3: =IF($U3<>"",'HPDB FDT-2'!$BB11,"") | AP3: =IF($U3<>"","RFS","") | AR3: =IF($U3<>"","31","") | AS3: =IF($U3<>"","FALSE","") | AT3: =IF($U3<>"","TRUE","")
